<?xml version="1.0"?>
<robot xmlns:xacro="http://www.ros.org/wiki/xacro">

<!--definition of macro -->
<xacro:macro name="t_module" params="parent name *origin">

<!-- joint between parent-link and module_Link -->
  <joint name="${name}_joint_0" type="fixed" >
    <insert_block name="origin" />
    <parent link="${parent}" />
    <child link="${name}_link" />
  </joint>
  
  <link  name="${name}_link">
    <inertial>
      <origin xyz="-0.0180255383176995 2.00182271818558E-05 0.063920300127545"  rpy="0 0 0" />
      <mass   value="0.832217409872162" />
      <inertia ixx="0.00162292630009161" ixy="5.16386324388829E-07" ixz="-5.38220794323839E-05"
        	iyy="0.00161884419291852" iyz="-1.03737233460529E-06" izz="0.000486359497324985" />
    </inertial>
    <visual>
      <origin  xyz="0 0 0"   rpy="0 0 0" />
      <geometry>
        <mesh filename="package://mr_description/meshes/t_link.STL" />
      </geometry>
      <material  name="">
        <color rgba="0.8 0 0 1" />
      </material>
    </visual>
    <collision>
      <origin  xyz="0 0 0.034"    rpy="0 0 0" />
      <geometry>
<!--        <mesh filename="package://mr_description/meshes/t_link.STL" />-->
	<cylinder radius="0.0425" length="0.052"  />
      </geometry>
    </collision>
  </link>
  
  <link name="${name}_Offset_Link">
    <visual>
      <origin xyz="0 0 0.0825" rpy="0 0 0" />
      <geometry>
        <mesh filename="package://mr_description/meshes/t_link2.STL" />
      </geometry>
      <material name="">
        <color  rgba="0.86667 0 0 1" />
      </material>
    </visual>
    <collision>
      <origin xyz="0 0 0.0175" rpy="0 0 0" />
      <geometry>
<!--        <mesh filename="package://mr_description/meshes/t_link2.STL" />-->
	<cylinder radius="0.0425" length="0.125"  />
      </geometry>
    </collision>
    <inertial>
      <origin xyz="-0.01642 2.1934E-05 -0.007293"  rpy="0 0 0" />
      <mass  value="0.98367" />
      <inertia  ixx="0.0012164"  ixy="8.6247E-07"  ixz="7.8271E-05"
        	iyy="0.00097611" iyz="-1.2736E-07" izz="0.00062614" />
    </inertial>
  </link>
  
  <joint  name="${name}_Joint" type="revolute">
    <origin xyz="0 0 0.131" rpy="0 0 3.1416" />
    <parent link="${name}_link" />
    <child link="${name}_Offset_Link" />
    <axis  xyz="1 0 0" />
    <limit lower="-2.09" upper="2.09" effort="28" velocity="2.09" />
    <calibration   rising="0"   falling="0" />
    <dynamics      damping="0"  friction="0" />
<!--    <safety_controller soft_upper="-2.07" soft_lower="2.07"  k_position="0" k_velocity="0" />-->
  </joint>
  
  <!--  reduction ratio-->
  <transmission name="${name}_trans">
    <type>transmission_interface/SimpleTransmission</type>
    <joint name="${name}_Joint">
      <hardwareInterface>PositionJointInterface</hardwareInterface>
      <hardwareInterface>VelocityJointInterface</hardwareInterface>
      <hardwareInterface>EffortJointInterface</hardwareInterface>      
    </joint>
    <actuator name="${name}_motor">
      <mechanicalReduction>200</mechanicalReduction> 
      <hardwareInterface>PositionJointInterface</hardwareInterface>
      <hardwareInterface>VelocityJointInterface</hardwareInterface>
      <hardwareInterface>EffortJointInterface</hardwareInterface>      
    </actuator>
  </transmission>

<!--Joint between Offset_Link and Lockring_Link-->
  <joint name="${name}_Offset_Joint" type="fixed">
    <origin xyz="0 0 0.0825" rpy="0 0 0"/>
    <parent link="${name}_Offset_Link"/>
    <child link="${name}_Link"/>
  </joint>

<!--the Lockring_Link in T module-->
  <link name="${name}_Link">
<!--    <collision>-->
<!--      <origin xyz="0 0 0" rpy="0 0 0" />-->
<!--      <geometry>-->
<!--        <mesh filename="package://mr_description/meshes/VT_InLink.STL" />-->
<!--      </geometry>-->
<!--    </collision>-->
  </link>

  
  </xacro:macro>
</robot>
