<robot name="T_module">

<!--the front visual link in T module-->
  <link name="VT_InLink">
    <inertial>
      <origin xyz="2.9038E-18 -2.1866E-18 0.0015" rpy="0 0 0" />
      <mass   value="8.4823E-05" />
      <inertia ixx="2.5447E-10" ixy="-1.2925E-27" ixz="4.3983E-28"
               iyy="2.5447E-10" iyz="3.5597E-27"  izz="3.817E-10" />
    </inertial>
    <visual>
      <origin   xyz="0 0 0"  rpy="0 0 0" />
      <geometry>
        <mesh   filename="package://mr_description/meshes/VT_InLink.STL" />
      </geometry>
      <material  name="">
        <color   rgba="1 1 1 1" />
      </material>
    </visual>
    <collision>
      <origin  xyz="0 0 0" rpy="0 0 0" />
      <geometry>
        <mesh filename="package://mr_description/meshes/VT_InLink.STL" />
      </geometry>
    </collision>
  </link>

<!--the front link in T module and the joint fixed with the front visual link-->
  <link  name="T_InLink">
    <inertial>
      <origin xyz="4.5327E-06 0.014724 0.10236" rpy="0 0 0" />
      <mass   value="0.8287" />
      <inertia   ixx="0.0027398"  ixy="-8.0424E-07"  ixz="-2.3991E-06"
       					 iyy="0.0028894"  iyz="0.00016467"   izz="0.00086451" />
    </inertial>
    <visual>
      <origin  xyz="0 0 0"  rpy="0 0 0" />
      <geometry>
        <mesh  filename="package://mr_description/meshes/T_InLink.STL" />
      </geometry>
      <material name="">
        <color  rgba="1 0 0 1" />
      </material>
    </visual>
    <collision>
      <origin  xyz="0 0 0"  rpy="0 0 0" />
      <geometry>
        <mesh filename="package://mr_description/meshes/T_InLink.STL" />
      </geometry>
    </collision>
  </link>
  <joint name="V_InJoint" type="fixed">
    <origin  xyz="0 0 0" rpy="0 0 0" />
    <parent  link="VT_InLink" />
    <child   link="T_InLink" />
    <axis    xyz="0 0 0" />
    <limit  lower="0" upper="0"  effort="0"  velocity="0" />
  </joint>

<!--the backend link in T module the joint in T module-->
  <link  name="T_OutLink">
    <inertial>
      <origin xyz="2.0762E-05 -0.0094284 0.014486" rpy="0 0 0" />
      <mass  value="1.4322" />
      <inertia   ixx="0.0018144"  ixy="-1.0634E-06"  ixz="9.3521E-08"
      					 iyy="0.0011673"  iyz="8.3209E-05"  izz="0.0023046" />
    </inertial>
    <visual>
      <origin  xyz="0 0 0"  rpy="0 0 0" />
      <geometry>
        <mesh  filename="package://mr_description/meshes/T_OutLink.STL" />
      </geometry>
      <material  name="">
        <color  rgba="1 0 0 1" />
      </material>
    </visual>
    <collision>
      <origin  xyz="0 0 0"  rpy="0 0 0" />
      <geometry>
        <mesh  filename="package://mr_description/meshes/T_OutLink.STL" />
      </geometry>
    </collision>
  </link>
  <joint  name="T_Joint"  type="revolute">
    <origin  xyz="0 0 0.1466"  rpy="-1.5708 1.2251E-16 -3.1416" />
    <parent  link="T_InLink" />
    <child  link="T_OutLink" />
    <axis  xyz="0 0 1" />
    <limit  lower="-2.07" upper="2.07"  effort="0"  velocity="0" />
  </joint>

<!--the back visual link in T module and the joint fixed with the back visual link-->
  <link  name="VT_OutLink">
    <inertial>
      <origin
        xyz="-2.7136E-19 9.8046E-20 -0.0015"
        rpy="0 0 0" />
      <mass
        value="8.4823E-05" />
      <inertia
        ixx="2.5447E-10"
        ixy="0"
        ixz="-1.9769E-26"
        iyy="2.5447E-10"
        iyz="9.4423E-27"
        izz="3.817E-10" />
    </inertial>
		<visual>
      <origin  xyz="0 0 0"  rpy="0 0 0" />
      <geometry>
        <mesh  filename="package://mr_description/meshes/VT_OutLink.STL" />
      </geometry>
      <material name="">
        <color  rgba="1 1 1 1" />
      </material>
    </visual>
  </link>

  <joint  name="V_OutJoint"  type="fixed">
    <origin  xyz="0 -0.0934 0"  rpy="-1.5708 -0.33352 3.1416" />
    <parent  link="T_OutLink" />
    <child  link="VT_OutLink" />
    <axis  xyz="0 0 0" />
    <limit  lower="0"  upper="0"  effort="0"  velocity="0" />
    <calibration  rising="0"  falling="0" />
    <dynamics  damping="0"  friction="0" />
    <safety_controller  soft_upper="0"  soft_lower="0"  k_position="0"  k_velocity="0" />
  </joint>
</robot>
