<?xml version="1.0" ?>
<!-- =================================================================================== -->
<!-- |    This document was autogenerated by xacro from climbot.urdf.xacro             | -->
<!-- |    EDITING THIS FILE BY HAND IS NOT RECOMMENDED                                 | -->
<!-- =================================================================================== -->
<robot name="climbot" xmlns:xacro="http://www.ros.org/wiki/xacro">
  <!-- materials for visualization -->
  <material name="Orange">
    <color rgba="1.0 0.4 0.0 1.0"/>
  </material>
  <material name="Grey">
    <color rgba="0.7 0.7 0.7 1.0"/>
  </material>
  <material name="DarkGrey">
    <color rgba="0.3 0.3 0.3 1.0"/>
  </material>
  <material name="White">
    <color rgba="1.0 1.0 1.0 1.0"/>
  </material>
  <material name="Black">
    <color rgba="0.0 0.0 0.0 1.0"/>
  </material>
  <material name="Red">
    <color rgba="1.0 0.0 0.0 1.0"/>
  </material>
  <material name="Green">
    <color rgba="0.0 1.0 0.0 1.0"/>
  </material>
  <material name="Blue">
    <color rgba="0.0 0.0 0.8 1.0"/>
  </material>
  <material name="LightGrey">
    <color rgba="0.82 0.82 0.82 1.0"/>
  </material>
  <!-- I Module -->
  <!--definition of default_inertial -->
  <!-- T Module -->
  <!--definition of default_inertial -->
  <!-- T Invert Module -->
  <!--definition of default_inertial -->
  <!-- Gripper100 Module -->
  <!--definition of default_inertial -->
  <!-- Gripper100 invert Module -->
  <!--definition of default_inertial -->
  <!-- Now we can start using the macros included above to define the actual robot -->
  <!-- The first use of a macro.  This one was defined in base.urdf.xacro above.
       A macro like this will expand to a set of link and joint definitions, and to additional
       Gazebo-related extensions (sensor plugins, etc).  The macro takes an argument, name, 
       that equals "base", and uses it to generate names for its component links and joints 
       (e.g., base_link).  The included origin block is also an argument to the macro.  By convention, 
       the origin block defines where the component is w.r.t its parent (in this case the parent 
       is the world frame). For more, see http://www.ros.org/wiki/xacro -->
  <!--    climbot move group 1-->
  <link name="base_gripper1"/>
  <!--  <link name="${name}_tcp" />-->
  <!-- joint between tcp_link and palm _Link -->
  <joint name="G0_joint_0" type="fixed">
    <origin rpy="-1.57079632679 0 0" xyz="0 0 0.17836"/>
    <child link="G0_palm_link"/>
    <!--    <parent link="${name}_tcp" />-->
    <parent link="base_gripper1"/>
  </joint>
  <!--the palm link-->
  <link name="G0_palm_link">
    <inertial>
      <origin rpy="0 0 0" xyz="-0.000330111921985683 0.0532067396112178 -0.00203994238779312"/>
      <mass value="1.0043961075726"/>
      <inertia ixx="0.00113334295507504" ixy="8.90230328283654E-06" ixz="-1.34473831837329E-06" iyy="0.000914211060471031" iyz="-6.54903141389812E-05" izz="0.00129135037593152"/>
    </inertial>
    <visual>
      <origin rpy="0 0 0" xyz="0 0 0"/>
      <geometry>
        <mesh filename="package://mr_description/meshes/palm_link.STL"/>
      </geometry>
      <material name="">
        <color rgba="0.1 0.1 0.1 1"/>
      </material>
    </visual>
    <collision>
      <origin rpy="1.57079632679 0 0" xyz="0 0.065 0"/>
      <!--      <origin xyz="0 0 0" rpy="0 0 0" />-->
      <geometry>
        <cylinder length="0.12" radius="0.05"/>
        <!--        <mesh filename="package://mr_description/meshes/palm_link.STL" />-->
      </geometry>
    </collision>
  </link>
  <!--  joint between the palm and the left finger-->
  <joint name="G0_finger_joint_l" type="prismatic">
    <origin rpy="0 0 0" xyz="0.038 0 0"/>
    <parent link="G0_palm_link"/>
    <child link="G0_finger_link_l"/>
    <axis xyz="-1 0 0"/>
    <limit effort="0" lower="0" upper="0.04" velocity="0"/>
    <dynamics damping="1" friction="1"/>
  </joint>
  <!--  the left finger link-->
  <link name="G0_finger_link_l">
    <inertial>
      <origin rpy="0 0 0" xyz="-0.053748 0.15337 2.2717E-07"/>
      <mass value="0.89853"/>
      <inertia ixx="0.0023606" ixy="-0.00017835" ixz="4.9579E-09" iyy="0.00087228" iyz="-8.5058E-09" izz="0.0018271"/>
    </inertial>
    <visual>
      <origin rpy="0 0 0" xyz="0 0 0"/>
      <geometry>
        <mesh filename="package://mr_description/meshes/finger_link_l.STL"/>
      </geometry>
      <material name="">
        <color rgba="0.52941 0.54902 0.54902 1"/>
      </material>
    </visual>
    <collision>
      <origin rpy="0 0 0" xyz="-0.05 0.18 0"/>
      <!--      <origin  xyz="0 0 0" rpy="0 0 0" />-->
      <geometry>
        <box size="0.01 0.1 0.1"/>
        <!--        <mesh filename="package://mr_description/meshes/finger_link_l.STL" />-->
      </geometry>
    </collision>
  </link>
  <!--  joint between the right finger and the palm-->
  <joint name="G0_finger_joint_r" type="prismatic">
    <origin rpy="0 0 0" xyz="-0.038 0 0"/>
    <parent link="G0_palm_link"/>
    <child link="G0_finger_link_r"/>
    <axis xyz="1 0 0"/>
    <limit effort="0" lower="0" upper="0.04" velocity="0"/>
    <dynamics damping="1" friction="1"/>
  </joint>
  <!-- the right finger link-->
  <link name="G0_finger_link_r">
    <inertial>
      <origin rpy="0 0 0" xyz="0.053748 0.15337 -2.2717E-07"/>
      <mass value="0.89853"/>
      <inertia ixx="0.0023606" ixy="0.00017835" ixz="4.9579E-09" iyy="0.00087228" iyz="8.5058E-09" izz="0.0018271"/>
    </inertial>
    <visual>
      <origin rpy="0 0 0" xyz="0 0 0"/>
      <geometry>
        <mesh filename="package://mr_description/meshes/finger_link_r.STL"/>
      </geometry>
      <material name="">
        <color rgba="0.52941 0.54902 0.54902 1"/>
      </material>
    </visual>
    <collision>
      <origin rpy="0 0 0" xyz="0.05 0.18 0"/>
      <!--      <origin xyz="0 0 0" rpy="0 0 0" />-->
      <geometry>
        <box size="0.01 0.1 0.1"/>
        <!--        <mesh filename="package://mr_description/meshes/finger_link_r.STL" />-->
      </geometry>
    </collision>
  </link>
  <!-- joint between base_link and Lockring_Link -->
  <joint name="I1_joint_0" type="fixed">
    <origin rpy="1.57079632679 0 0" xyz="0 0 0"/>
    <parent link="G0_palm_link"/>
    <child link="I1_Lr_Link_0"/>
  </joint>
  <!--the Lockring_Link in I module-->
  <link name="I1_Lr_Link_0">
    <inertial>
      <origin rpy="0 0 1" xyz="1.7347E-18 4.5022E-17 0.0028047"/>
      <mass value="0.0017728"/>
      <inertia ixx="2.1769E-06" ixy="-6.7209E-37" ixz="8.0356E-39" iyy="2.1769E-06" iyz="-1.0785E-36" izz="4.3442E-06"/>
    </inertial>
    <visual>
      <origin rpy="0 0 0" xyz="0 0 0"/>
      <geometry>
        <mesh filename="package://mr_description/meshes/VI_InLink.STL"/>
      </geometry>
      <material name="White"/>
    </visual>
    <!--    <collision>-->
    <!--      <origin xyz="0 0 0" rpy="0 0 0" />-->
    <!--      <geometry>-->
    <!--        <mesh filename="package://mr_description/meshes/VI_InLink.STL" />-->
    <!--      </geometry>-->
    <!--    </collision>-->
  </link>
  <!-- joint between Lockring_Link and IModule_InLink -->
  <joint name="I1_Lr_Joint_1" type="fixed">
    <origin rpy="0 0 0" xyz="0 0 0"/>
    <parent link="I1_Lr_Link_0"/>
    <child link="I1_InLink_1"/>
    <axis xyz="0 0 0"/>
    <limit effort="0" lower="0" upper="0" velocity="0"/>
  </joint>
  <!--the IModule_InLink in I module-->
  <link name="I1_InLink_1">
    <inertial>
      <origin rpy="0 0 0" xyz="0.0024379 -0.0024994 0.076186"/>
      <mass value="0.58944"/>
      <inertia ixx="0.0012341" ixy="-3.8775E-05" ixz="-3.5596E-05" iyy="0.001235" iyz="3.487E-05" izz="0.00097195"/>
    </inertial>
    <visual>
      <origin rpy="0 0 0" xyz="0 0 0"/>
      <geometry>
        <mesh filename="package://mr_description/meshes/I_InLink.STL"/>
      </geometry>
      <material name="Red"/>
    </visual>
    <collision>
      <!--      <origin   xyz="0 0 0"  rpy="0 0 0" />-->
      <origin rpy="0 0 0" xyz="0 0 0.083"/>
      <geometry>
        <!--        <mesh   filename="package://mr_description/meshes/I_InLink.STL" />-->
        <cylinder length="0.158" radius="0.05"/>
      </geometry>
    </collision>
  </link>
  <!-- joint between IModule_InLink and IModule_OutLink -->
  <joint name="I1_Joint_2" type="revolute">
    <origin rpy="0 0 0" xyz="0 0 0.12015"/>
    <parent link="I1_InLink_1"/>
    <child link="I1_OutLink_2"/>
    <axis xyz="0 0 1"/>
    <limit effort="0" lower="-3.14" upper="3.14" velocity="0"/>
  </joint>
  <!--the IModule_OutLink in I module-->
  <link name="I1_OutLink_2">
    <inertial>
      <origin rpy="0 0 0" xyz="-2.1654E-06 1.6134E-06 0.015967"/>
      <mass value="1.185"/>
      <inertia ixx="0.0008146" ixy="-5.4911E-08" ixz="-2.4725E-08" iyy="0.00081463" iyz="1.7434E-08" izz="0.0013197"/>
    </inertial>
    <visual>
      <origin rpy="0 0 0" xyz="0 0 0"/>
      <geometry>
        <mesh filename="package://mr_description/meshes/I_OutLink.STL"/>
      </geometry>
      <material name="Red"/>
    </visual>
    <!--    <collision>-->
    <!--      <origin  xyz="0 0 0" rpy="0 0 0" />-->
    <!--      <geometry>-->
    <!--        <mesh  filename="package://mr_description/meshes/I_OutLink.STL" />-->
    <!--      </geometry>-->
    <!--    </collision>-->
  </link>
  <!-- joint between IModule_OutLink and Lockring_Link -->
  <joint name="I1_Lr_Joint_3" type="fixed">
    <origin rpy="0 0 0" xyz="0 0 0.0432"/>
    <parent link="I1_OutLink_2"/>
    <child link="I1_Lr_Link_3"/>
    <axis xyz="0 0 0"/>
    <limit effort="0" lower="0" upper="0" velocity="0"/>
  </joint>
  <!--the Lockring_Link in I module-->
  <link name="I1_Lr_Link_3">
    <inertial>
      <origin rpy="0 0 0" xyz="-1.7347E-18 4.5159E-17 -0.00285"/>
      <mass value="0.0017728"/>
      <inertia ixx="2.1769E-06" ixy="-9.5009E-37" ixz="1.6071E-38" iyy="2.1769E-06" iyz="-1.0575E-36" izz="4.3442E-06"/>
    </inertial>
    <visual>
      <origin rpy="0 0 0" xyz="0 0 0"/>
      <geometry>
        <mesh filename="package://mr_description/meshes/VI_OutLink.STL"/>
      </geometry>
      <material name="White"/>
    </visual>
    <!--    <collision>-->
    <!--      <origin  xyz="0 0 0" rpy="0 0 0" />-->
    <!--      <geometry>-->
    <!--        <mesh  filename="package://mr_description/meshes/VI_OutLink.STL" />-->
    <!--      </geometry>-->
    <!--    </collision>-->
  </link>
  <!-- joint between base_link and Lockring_Link -->
  <joint name="T2_joint_0" type="fixed">
    <origin rpy="0 0 0" xyz="0 0 0"/>
    <parent link="I1_Lr_Link_3"/>
    <child link="T2_Lr_Link_0"/>
  </joint>
  <!--the Lockring_Link in T module-->
  <link name="T2_Lr_Link_0">
    <inertial>
      <origin rpy="0 0 0" xyz="2.9038E-18 -2.1866E-18 0.0015"/>
      <mass value="8.4823E-05"/>
      <inertia ixx="2.5447E-10" ixy="-1.2925E-27" ixz="4.3983E-28" iyy="2.5447E-10" iyz="3.5597E-27" izz="3.817E-10"/>
    </inertial>
    <visual>
      <origin rpy="0 0 0" xyz="0 0 0"/>
      <geometry>
        <mesh filename="package://mr_description/meshes/VT_InLink.STL"/>
      </geometry>
      <material name="White"/>
    </visual>
    <!--    <collision>-->
    <!--      <origin xyz="0 0 0" rpy="0 0 0" />-->
    <!--      <geometry>-->
    <!--        <mesh filename="package://mr_description/meshes/VT_InLink.STL" />-->
    <!--      </geometry>-->
    <!--    </collision>-->
  </link>
  <!-- joint between Lockring_Link and TModule_InLink -->
  <joint name="T2_Lr_Joint_1" type="fixed">
    <origin rpy="0 0 0" xyz="0 0 0"/>
    <parent link="T2_Lr_Link_0"/>
    <child link="T2_InLink_1"/>
    <axis xyz="0 0 0"/>
    <limit effort="0" lower="0" upper="0" velocity="0"/>
  </joint>
  <!--the TModule_InLink in T module-->
  <link name="T2_InLink_1">
    <inertial>
      <origin rpy="0 0 0" xyz="4.5327E-06 0.014724 0.10236"/>
      <mass value="0.8287"/>
      <inertia ixx="0.0027398" ixy="-8.0424E-07" ixz="-2.3991E-06" iyy="0.0028894" iyz="0.00016467" izz="0.00086451"/>
    </inertial>
    <visual>
      <origin rpy="0 0 0" xyz="0 0 0"/>
      <geometry>
        <mesh filename="package://mr_description/meshes/T_InLink.STL"/>
      </geometry>
      <material name="Red"/>
    </visual>
    <collision>
      <origin rpy="0 0 0" xyz="0 0 0.04"/>
      <!--      <origin   xyz="0 0 0"  rpy="0 0 0" />-->
      <geometry>
        <cylinder length="0.07" radius="0.05"/>
        <!--        <mesh   filename="package://mr_description/meshes/T_InLink.STL" />-->
      </geometry>
    </collision>
  </link>
  <!-- joint between TModule_InLink and TModule_OutLink -->
  <joint name="T2_Joint_2" type="revolute">
    <origin rpy="-1.5708 1.2251E-16 -3.1416" xyz="0 0 0.1466"/>
    <parent link="T2_InLink_1"/>
    <child link="T2_OutLink_2"/>
    <axis xyz="0 0 1"/>
    <limit effort="0" lower="-2.07" upper="2.07" velocity="0"/>
  </joint>
  <!--the TModule_OutLink in T module-->
  <link name="T2_OutLink_2">
    <inertial>
      <origin rpy="0 0 0" xyz="2.0762E-05 -0.0094284 0.014486"/>
      <mass value="1.4322"/>
      <inertia ixx="0.0018144" ixy="-1.0634E-06" ixz="9.3521E-08" iyy="0.0011673" iyz="8.3209E-05" izz="0.0023046"/>
    </inertial>
    <visual>
      <origin rpy="0 0 0" xyz="0 0 0"/>
      <geometry>
        <mesh filename="package://mr_description/meshes/T_OutLink.STL"/>
      </geometry>
      <material name="Red"/>
    </visual>
    <collision>
      <origin rpy="1.57079632679 0 0" xyz="0 -0.025 0"/>
      <!--      <origin  xyz="0 0 0" rpy="0 0 0" />-->
      <geometry>
        <cylinder length="0.12" radius="0.05"/>
        <!--        <mesh  filename="package://mr_description/meshes/T_OutLink.STL" />-->
      </geometry>
    </collision>
  </link>
  <!-- joint between TModule_OutLink and Lockring_Link -->
  <joint name="T2_Lr_Joint_3" type="fixed">
    <origin rpy="-1.5708 0 3.1416" xyz="0 -0.0934 0"/>
    <parent link="T2_OutLink_2"/>
    <child link="T2_Lr_Link_3"/>
    <axis xyz="0 0 0"/>
    <limit effort="0" lower="0" upper="0" velocity="0"/>
  </joint>
  <!--the Lockring_Link in T module-->
  <link name="T2_Lr_Link_3">
    <inertial>
      <origin rpy="0 0 0" xyz="-2.7136E-19 9.8046E-20 -0.0015"/>
      <mass value="8.4823E-05"/>
      <inertia ixx="2.5447E-10" ixy="0" ixz="-1.9769E-26" iyy="2.5447E-10" iyz="9.4423E-27" izz="3.817E-10"/>
    </inertial>
    <visual>
      <origin rpy="0 0 0" xyz="0 0 0"/>
      <geometry>
        <mesh filename="package://mr_description/meshes/VT_OutLink.STL"/>
      </geometry>
      <material name="White"/>
    </visual>
    <!--    <collision>-->
    <!--      <origin  xyz="0 0 0" rpy="0 0 0" />-->
    <!--      <geometry>-->
    <!--        <mesh  filename="package://mr_description/meshes/VT_OutLink.STL" />-->
    <!--      </geometry>-->
    <!--    </collision>   -->
  </link>
  <!-- joint between base_link and Lockring_Link -->
  <joint name="T3_joint_0" type="fixed">
    <origin rpy="0 0 0" xyz="0 0 0.005"/>
    <!--    <origin xyz="0 0 0.005" rpy="0 0 0" />-->
    <parent link="T2_Lr_Link_3"/>
    <child link="T3_Lr_Link_3"/>
  </joint>
  <!--the Lockring_Link in T module-->
  <link name="T3_Lr_Link_3">
    <inertial>
      <origin rpy="0 0 0" xyz="-2.7136E-19 9.8046E-20 -0.0015"/>
      <mass value="8.4823E-05"/>
      <inertia ixx="2.5447E-10" ixy="0" ixz="-1.9769E-26" iyy="2.5447E-10" iyz="9.4423E-27" izz="3.817E-10"/>
    </inertial>
    <visual>
      <origin rpy="0 0 0" xyz="0 0 0"/>
      <geometry>
        <mesh filename="package://mr_description/meshes/VT_OutLink.STL"/>
      </geometry>
      <material name="White"/>
    </visual>
    <!--    <collision>-->
    <!--      <origin  xyz="0 0 0" rpy="0 0 0" />-->
    <!--      <geometry>-->
    <!--        <mesh  filename="package://mr_description/meshes/VT_OutLink.STL" />-->
    <!--      </geometry>-->
    <!--    </collision>   -->
  </link>
  <!-- joint between TModule_OutLink and Lockring_Link -->
  <joint name="T3_Lr_Joint_3" type="fixed">
    <origin rpy="-1.57079632679 3.1416 3.1416" xyz="0 0 0.0884"/>
    <child link="T3_OutLink_2"/>
    <parent link="T3_Lr_Link_3"/>
    <axis xyz="0 0 0"/>
    <limit effort="0" lower="0" upper="0" velocity="0"/>
  </joint>
  <!--the TModule_OutLink in T module-->
  <link name="T3_OutLink_2">
    <inertial>
      <origin rpy="0 0 0" xyz="2.0762E-05 -0.0094284 0.014486"/>
      <mass value="1.4322"/>
      <inertia ixx="0.0018144" ixy="-1.0634E-06" ixz="9.3521E-08" iyy="0.0011673" iyz="8.3209E-05" izz="0.0023046"/>
    </inertial>
    <visual>
      <origin rpy="0 0 0" xyz="0 0 0"/>
      <geometry>
        <mesh filename="package://mr_description/meshes/T_OutLink.STL"/>
      </geometry>
      <material name="Red"/>
    </visual>
    <collision>
      <origin rpy="1.57079632679 0 0" xyz="0 -0.03 0"/>
      <!--      <origin  xyz="0 0 0" rpy="0 0 0" />-->
      <geometry>
        <cylinder length="0.12" radius="0.05"/>
        <!--        <mesh  filename="package://mr_description/meshes/T_OutLink.STL" />-->
      </geometry>
    </collision>
  </link>
  <!-- joint between TModule_InLink and TModule_OutLink -->
  <joint name="T3_Joint_2" type="revolute">
    <origin rpy="4.7124 -1.2251E-16 3.1416" xyz=" 0 0 0"/>
    <!--    <origin  xyz=" 0 0 -0.1466"  rpy="4.7124 -1.2251E-16 3.1416" />-->
    <child link="T3_InLink_1"/>
    <parent link="T3_OutLink_2"/>
    <axis xyz="0 1 0"/>
    <limit effort="0" lower="-2.07" upper="2.07" velocity="0"/>
  </joint>
  <!--the TModule_InLink in T module-->
  <link name="T3_InLink_1">
    <inertial>
      <origin rpy="0 0 0" xyz="4.5327E-06 0.014724 -0.04424"/>
      <!--      <origin xyz="4.5327E-06 0.014724 0.10236-0.1466" rpy="0 0 0" />-->
      <mass value="0.8287"/>
      <inertia ixx="0.0027398" ixy="-8.0424E-07" ixz="-2.3991E-06" iyy="0.0028894" iyz="0.00016467" izz="0.00086451"/>
    </inertial>
    <visual>
      <origin rpy="0 0 0" xyz="0 0 -0.1466"/>
      <geometry>
        <mesh filename="package://mr_description/meshes/T_InLink.STL"/>
      </geometry>
      <material name="Red"/>
    </visual>
    <collision>
      <origin rpy="0 0 0" xyz="0 0 -0.11"/>
      <!--      <origin   xyz="0 0 -0.1466"  rpy="0 0 0" />-->
      <geometry>
        <cylinder length="0.07" radius="0.05"/>
        <!--        <mesh   filename="package://mr_description/meshes/T_InLink.STL" />-->
      </geometry>
    </collision>
  </link>
  <!-- joint between Lockring_Link and TModule_InLink -->
  <joint name="T3_Lr_Joint_1" type="fixed">
    <origin rpy="0 3.1416 0" xyz="0 0 -0.1416"/>
    <child link="T3_Lr_Link_0"/>
    <parent link="T3_InLink_1"/>
    <axis xyz="0 0 0"/>
    <limit effort="0" lower="0" upper="0" velocity="0"/>
  </joint>
  <!--the Lockring_Link in T module-->
  <link name="T3_Lr_Link_0">
    <inertial>
      <origin rpy="0 0 0" xyz="2.9038E-18 -2.1866E-18 0.0015"/>
      <mass value="8.4823E-05"/>
      <inertia ixx="2.5447E-10" ixy="-1.2925E-27" ixz="4.3983E-28" iyy="2.5447E-10" iyz="3.5597E-27" izz="3.817E-10"/>
    </inertial>
    <visual>
      <origin rpy="0 0 0" xyz="0 0 0"/>
      <geometry>
        <mesh filename="package://mr_description/meshes/VT_InLink.STL"/>
      </geometry>
      <material name="White"/>
    </visual>
    <!--    <collision>-->
    <!--      <origin xyz="0 0 0" rpy="0 0 0" />-->
    <!--      <geometry>-->
    <!--        <mesh filename="package://mr_description/meshes/VT_InLink.STL" />-->
    <!--      </geometry>-->
    <!--    </collision>-->
  </link>
  <!-- joint between base_link and Lockring_Link -->
  <joint name="T4_joint_0" type="fixed">
    <origin rpy="0 0 0" xyz="0 0 0"/>
    <parent link="T3_Lr_Link_0"/>
    <child link="T4_Lr_Link_0"/>
  </joint>
  <!--the Lockring_Link in T module-->
  <link name="T4_Lr_Link_0">
    <inertial>
      <origin rpy="0 0 0" xyz="2.9038E-18 -2.1866E-18 0.0015"/>
      <mass value="8.4823E-05"/>
      <inertia ixx="2.5447E-10" ixy="-1.2925E-27" ixz="4.3983E-28" iyy="2.5447E-10" iyz="3.5597E-27" izz="3.817E-10"/>
    </inertial>
    <visual>
      <origin rpy="0 0 0" xyz="0 0 0"/>
      <geometry>
        <mesh filename="package://mr_description/meshes/VT_InLink.STL"/>
      </geometry>
      <material name="White"/>
    </visual>
    <!--    <collision>-->
    <!--      <origin xyz="0 0 0" rpy="0 0 0" />-->
    <!--      <geometry>-->
    <!--        <mesh filename="package://mr_description/meshes/VT_InLink.STL" />-->
    <!--      </geometry>-->
    <!--    </collision>-->
  </link>
  <!-- joint between Lockring_Link and TModule_InLink -->
  <joint name="T4_Lr_Joint_1" type="fixed">
    <origin rpy="0 0 0" xyz="0 0 0"/>
    <parent link="T4_Lr_Link_0"/>
    <child link="T4_InLink_1"/>
    <axis xyz="0 0 0"/>
    <limit effort="0" lower="0" upper="0" velocity="0"/>
  </joint>
  <!--the TModule_InLink in T module-->
  <link name="T4_InLink_1">
    <inertial>
      <origin rpy="0 0 0" xyz="4.5327E-06 0.014724 0.10236"/>
      <mass value="0.8287"/>
      <inertia ixx="0.0027398" ixy="-8.0424E-07" ixz="-2.3991E-06" iyy="0.0028894" iyz="0.00016467" izz="0.00086451"/>
    </inertial>
    <visual>
      <origin rpy="0 0 0" xyz="0 0 0"/>
      <geometry>
        <mesh filename="package://mr_description/meshes/T_InLink.STL"/>
      </geometry>
      <material name="Red"/>
    </visual>
    <collision>
      <origin rpy="0 0 0" xyz="0 0 0.04"/>
      <!--      <origin   xyz="0 0 0"  rpy="0 0 0" />-->
      <geometry>
        <cylinder length="0.07" radius="0.05"/>
        <!--        <mesh   filename="package://mr_description/meshes/T_InLink.STL" />-->
      </geometry>
    </collision>
  </link>
  <!-- joint between TModule_InLink and TModule_OutLink -->
  <joint name="T4_Joint_2" type="revolute">
    <origin rpy="-1.5708 1.2251E-16 -3.1416" xyz="0 0 0.1466"/>
    <parent link="T4_InLink_1"/>
    <child link="T4_OutLink_2"/>
    <axis xyz="0 0 1"/>
    <limit effort="0" lower="-2.07" upper="2.07" velocity="0"/>
  </joint>
  <!--the TModule_OutLink in T module-->
  <link name="T4_OutLink_2">
    <inertial>
      <origin rpy="0 0 0" xyz="2.0762E-05 -0.0094284 0.014486"/>
      <mass value="1.4322"/>
      <inertia ixx="0.0018144" ixy="-1.0634E-06" ixz="9.3521E-08" iyy="0.0011673" iyz="8.3209E-05" izz="0.0023046"/>
    </inertial>
    <visual>
      <origin rpy="0 0 0" xyz="0 0 0"/>
      <geometry>
        <mesh filename="package://mr_description/meshes/T_OutLink.STL"/>
      </geometry>
      <material name="Red"/>
    </visual>
    <collision>
      <origin rpy="1.57079632679 0 0" xyz="0 -0.025 0"/>
      <!--      <origin  xyz="0 0 0" rpy="0 0 0" />-->
      <geometry>
        <cylinder length="0.12" radius="0.05"/>
        <!--        <mesh  filename="package://mr_description/meshes/T_OutLink.STL" />-->
      </geometry>
    </collision>
  </link>
  <!-- joint between TModule_OutLink and Lockring_Link -->
  <joint name="T4_Lr_Joint_3" type="fixed">
    <origin rpy="-1.5708 0 3.1416" xyz="0 -0.0934 0"/>
    <parent link="T4_OutLink_2"/>
    <child link="T4_Lr_Link_3"/>
    <axis xyz="0 0 0"/>
    <limit effort="0" lower="0" upper="0" velocity="0"/>
  </joint>
  <!--the Lockring_Link in T module-->
  <link name="T4_Lr_Link_3">
    <inertial>
      <origin rpy="0 0 0" xyz="-2.7136E-19 9.8046E-20 -0.0015"/>
      <mass value="8.4823E-05"/>
      <inertia ixx="2.5447E-10" ixy="0" ixz="-1.9769E-26" iyy="2.5447E-10" iyz="9.4423E-27" izz="3.817E-10"/>
    </inertial>
    <visual>
      <origin rpy="0 0 0" xyz="0 0 0"/>
      <geometry>
        <mesh filename="package://mr_description/meshes/VT_OutLink.STL"/>
      </geometry>
      <material name="White"/>
    </visual>
    <!--    <collision>-->
    <!--      <origin  xyz="0 0 0" rpy="0 0 0" />-->
    <!--      <geometry>-->
    <!--        <mesh  filename="package://mr_description/meshes/VT_OutLink.STL" />-->
    <!--      </geometry>-->
    <!--    </collision>   -->
  </link>
  <!-- joint between base_link and Lockring_Link -->
  <joint name="I5_joint_0" type="fixed">
    <origin rpy="0 0 0" xyz="0 0 0"/>
    <parent link="T4_Lr_Link_3"/>
    <child link="I5_Lr_Link_0"/>
  </joint>
  <!--the Lockring_Link in I module-->
  <link name="I5_Lr_Link_0">
    <inertial>
      <origin rpy="0 0 1" xyz="1.7347E-18 4.5022E-17 0.0028047"/>
      <mass value="0.0017728"/>
      <inertia ixx="2.1769E-06" ixy="-6.7209E-37" ixz="8.0356E-39" iyy="2.1769E-06" iyz="-1.0785E-36" izz="4.3442E-06"/>
    </inertial>
    <visual>
      <origin rpy="0 0 0" xyz="0 0 0"/>
      <geometry>
        <mesh filename="package://mr_description/meshes/VI_InLink.STL"/>
      </geometry>
      <material name="White"/>
    </visual>
    <!--    <collision>-->
    <!--      <origin xyz="0 0 0" rpy="0 0 0" />-->
    <!--      <geometry>-->
    <!--        <mesh filename="package://mr_description/meshes/VI_InLink.STL" />-->
    <!--      </geometry>-->
    <!--    </collision>-->
  </link>
  <!-- joint between Lockring_Link and IModule_InLink -->
  <joint name="I5_Lr_Joint_1" type="fixed">
    <origin rpy="0 0 0" xyz="0 0 0"/>
    <parent link="I5_Lr_Link_0"/>
    <child link="I5_InLink_1"/>
    <axis xyz="0 0 0"/>
    <limit effort="0" lower="0" upper="0" velocity="0"/>
  </joint>
  <!--the IModule_InLink in I module-->
  <link name="I5_InLink_1">
    <inertial>
      <origin rpy="0 0 0" xyz="0.0024379 -0.0024994 0.076186"/>
      <mass value="0.58944"/>
      <inertia ixx="0.0012341" ixy="-3.8775E-05" ixz="-3.5596E-05" iyy="0.001235" iyz="3.487E-05" izz="0.00097195"/>
    </inertial>
    <visual>
      <origin rpy="0 0 0" xyz="0 0 0"/>
      <geometry>
        <mesh filename="package://mr_description/meshes/I_InLink.STL"/>
      </geometry>
      <material name="Red"/>
    </visual>
    <collision>
      <!--      <origin   xyz="0 0 0"  rpy="0 0 0" />-->
      <origin rpy="0 0 0" xyz="0 0 0.083"/>
      <geometry>
        <!--        <mesh   filename="package://mr_description/meshes/I_InLink.STL" />-->
        <cylinder length="0.158" radius="0.05"/>
      </geometry>
    </collision>
  </link>
  <!-- joint between IModule_InLink and IModule_OutLink -->
  <joint name="I5_Joint_2" type="revolute">
    <origin rpy="0 0 0" xyz="0 0 0.12015"/>
    <parent link="I5_InLink_1"/>
    <child link="I5_OutLink_2"/>
    <axis xyz="0 0 1"/>
    <limit effort="0" lower="-3.14" upper="3.14" velocity="0"/>
  </joint>
  <!--the IModule_OutLink in I module-->
  <link name="I5_OutLink_2">
    <inertial>
      <origin rpy="0 0 0" xyz="-2.1654E-06 1.6134E-06 0.015967"/>
      <mass value="1.185"/>
      <inertia ixx="0.0008146" ixy="-5.4911E-08" ixz="-2.4725E-08" iyy="0.00081463" iyz="1.7434E-08" izz="0.0013197"/>
    </inertial>
    <visual>
      <origin rpy="0 0 0" xyz="0 0 0"/>
      <geometry>
        <mesh filename="package://mr_description/meshes/I_OutLink.STL"/>
      </geometry>
      <material name="Red"/>
    </visual>
    <!--    <collision>-->
    <!--      <origin  xyz="0 0 0" rpy="0 0 0" />-->
    <!--      <geometry>-->
    <!--        <mesh  filename="package://mr_description/meshes/I_OutLink.STL" />-->
    <!--      </geometry>-->
    <!--    </collision>-->
  </link>
  <!-- joint between IModule_OutLink and Lockring_Link -->
  <joint name="I5_Lr_Joint_3" type="fixed">
    <origin rpy="0 0 0" xyz="0 0 0.0432"/>
    <parent link="I5_OutLink_2"/>
    <child link="I5_Lr_Link_3"/>
    <axis xyz="0 0 0"/>
    <limit effort="0" lower="0" upper="0" velocity="0"/>
  </joint>
  <!--the Lockring_Link in I module-->
  <link name="I5_Lr_Link_3">
    <inertial>
      <origin rpy="0 0 0" xyz="-1.7347E-18 4.5159E-17 -0.00285"/>
      <mass value="0.0017728"/>
      <inertia ixx="2.1769E-06" ixy="-9.5009E-37" ixz="1.6071E-38" iyy="2.1769E-06" iyz="-1.0575E-36" izz="4.3442E-06"/>
    </inertial>
    <visual>
      <origin rpy="0 0 0" xyz="0 0 0"/>
      <geometry>
        <mesh filename="package://mr_description/meshes/VI_OutLink.STL"/>
      </geometry>
      <material name="White"/>
    </visual>
    <!--    <collision>-->
    <!--      <origin  xyz="0 0 0" rpy="0 0 0" />-->
    <!--      <geometry>-->
    <!--        <mesh  filename="package://mr_description/meshes/VI_OutLink.STL" />-->
    <!--      </geometry>-->
    <!--    </collision>-->
  </link>
  <!-- joint between parent_link and palm _Link -->
  <joint name="G6_joint_0" type="fixed">
    <origin rpy="1.57079632679 0 0" xyz="0 0 0"/>
    <parent link="I5_Lr_Link_3"/>
    <child link="G6_palm_link"/>
  </joint>
  <!--the palm link-->
  <link name="G6_palm_link">
    <inertial>
      <origin rpy="0 0 0" xyz="-0.000330111921985683 0.0532067396112178 -0.00203994238779312"/>
      <mass value="1.0043961075726"/>
      <inertia ixx="0.00113334295507504" ixy="8.90230328283654E-06" ixz="-1.34473831837329E-06" iyy="0.000914211060471031" iyz="-6.54903141389812E-05" izz="0.00129135037593152"/>
    </inertial>
    <visual>
      <origin rpy="0 0 0" xyz="0 0 0"/>
      <geometry>
        <mesh filename="package://mr_description/meshes/palm_link.STL"/>
      </geometry>
      <material name="">
        <color rgba="0.1 0.1 0.1 1"/>
      </material>
    </visual>
    <collision>
      <origin rpy="1.57079632679 0 0" xyz="0 0.065 0"/>
      <!--      <origin  xyz="0 0 0"  rpy="0 0 0" />-->
      <geometry>
        <cylinder length="0.12" radius="0.05"/>
        <!--        <mesh filename="package://mr_description/meshes/palm_link.STL" />-->
      </geometry>
    </collision>
  </link>
  <!--  joint between the palm and the left finger-->
  <joint name="G6_finger_joint_l" type="prismatic">
    <origin rpy="0 0 0" xyz="0.038 0 0"/>
    <parent link="G6_palm_link"/>
    <child link="G6_finger_link_l"/>
    <axis xyz="-1 0 0"/>
    <limit effort="0" lower="0" upper="0.04" velocity="0"/>
    <dynamics damping="1" friction="1"/>
  </joint>
  <!--  the left finger link-->
  <link name="G6_finger_link_l">
    <inertial>
      <origin rpy="0 0 0" xyz="-0.053748 0.15337 2.2717E-07"/>
      <mass value="0.89853"/>
      <inertia ixx="0.0023606" ixy="-0.00017835" ixz="4.9579E-09" iyy="0.00087228" iyz="-8.5058E-09" izz="0.0018271"/>
    </inertial>
    <visual>
      <origin rpy="0 0 0" xyz="0 0 0"/>
      <geometry>
        <mesh filename="package://mr_description/meshes/finger_link_l.STL"/>
      </geometry>
      <material name="">
        <color rgba="0.52941 0.54902 0.54902 1"/>
      </material>
    </visual>
    <collision>
      <origin rpy="0 0 0" xyz="-0.05 0.18 0"/>
      <!--      <origin xyz="0 0 0" rpy="0 0 0" />-->
      <geometry>
        <box size="0.01 0.1 0.1"/>
        <!--        <mesh filename="package://mr_description/meshes/finger_link_l.STL" />-->
      </geometry>
    </collision>
  </link>
  <!--  joint between the right finger and the palm-->
  <joint name="G6_finger_joint_r" type="prismatic">
    <origin rpy="0 0 0" xyz="-0.038 0 0"/>
    <parent link="G6_palm_link"/>
    <child link="G6_finger_link_r"/>
    <axis xyz="1 0 0"/>
    <limit effort="0" lower="0" upper="0.04" velocity="0"/>
    <dynamics damping="1" friction="1"/>
  </joint>
  <!-- the right finger link-->
  <link name="G6_finger_link_r">
    <inertial>
      <origin rpy="0 0 0" xyz="0.053748 0.15337 -2.2717E-07"/>
      <mass value="0.89853"/>
      <inertia ixx="0.0023606" ixy="0.00017835" ixz="4.9579E-09" iyy="0.00087228" iyz="8.5058E-09" izz="0.0018271"/>
    </inertial>
    <visual>
      <origin rpy="0 0 0" xyz="0 0 0"/>
      <geometry>
        <mesh filename="package://mr_description/meshes/finger_link_r.STL"/>
      </geometry>
      <material name="">
        <color rgba="0.52941 0.54902 0.54902 1"/>
      </material>
    </visual>
    <collision>
      <origin rpy="0 0 0" xyz="0.05 0.18 0"/>
      <!--      <origin xyz="0 0 0" rpy="0 0 0" />-->
      <geometry>
        <box size="0.01 0.1 0.1"/>
        <!--        <mesh filename="package://mr_description/meshes/finger_link_r.STL" />-->
      </geometry>
    </collision>
  </link>
  <!--    joint between the palm link and the tcp-->
  <joint name="G6_tcp_joint" type="fixed">
    <origin rpy="0 0 0" xyz="0 0.17836 0"/>
    <parent link="G6_palm_link"/>
    <child link="G6_tcp"/>
    <axis xyz="0 0 0"/>
  </joint>
  <link name="G6_tcp"/>
  <!--    climbot move group 2-->
  <!--   <link name="base_gripper2" />-->
  <!--   -->
  <!--  <xacro:G_invert name="_G6" parent="base_gripper2">-->
  <!--    <origin xyz="0.2 0 0.17836" rpy="${-pi*0.5} 0 0" />-->
  <!--  </xacro:G_invert>-->
  <!--  <xacro:I_module name="_I5" parent="_G6_palm_link">-->
  <!--    <origin xyz="0 0 0" rpy="${pi*0.5} 0 0" />-->
  <!--  </xacro:I_module>-->
  <!--  <xacro:T_invert name="_T4" parent="_I5_Lr_Link_3">-->
  <!--    <origin xyz="0 0 0.005" rpy="0 0 0" />-->
  <!--  </xacro:T_invert>-->
  <!--  -->
  <!--  <xacro:T_module name="_T3" parent="_T4_Lr_Link_0">-->
  <!--    <origin xyz="0 0 0" rpy="0 0 0" />-->
  <!--  </xacro:T_module>-->
  <!--  <xacro:T_invert name="_T2" parent="_T3_Lr_Link_3">-->
  <!--    <origin xyz="0 0 0.005" rpy="0 0 0" />-->
  <!--  </xacro:T_invert>-->
  <!--  <xacro:I_module name="_I1" parent="_T2_Lr_Link_0">-->
  <!--    <origin xyz="0 0 0" rpy="0 0 0" />-->
  <!--  </xacro:I_module>-->
  <!--  -->
  <!--  <xacro:G_module name="_G0" parent="_I1_Lr_Link_3">-->
  <!--    <origin xyz="0 0 0" rpy="${pi*0.5} 0 0" />-->
  <!--  </xacro:G_module>-->
</robot>

