<?xml version="1.0" ?>
<!-- =================================================================================== -->
<!-- |    This document was autogenerated by xacro from manipulator6d.urdf.xacro       | -->
<!-- |    EDITING THIS FILE BY HAND IS NOT RECOMMENDED                                 | -->
<!-- =================================================================================== -->
<robot name="ModuleManipulator" xmlns:xacro="http://www.ros.org/wiki/xacro">
  <!-- materials for visualization -->
  <material name="Orange">
    <color rgba="1.0 0.4 0.0 1.0"/>
  </material>
  <material name="Grey">
    <color rgba="0.7 0.7 0.7 1.0"/>
  </material>
  <material name="DarkGrey">
    <color rgba="0.3 0.3 0.3 1.0"/>
  </material>
  <material name="White">
    <color rgba="1.0 1.0 1.0 1.0"/>
  </material>
  <material name="Black">
    <color rgba="0.0 0.0 0.0 1.0"/>
  </material>
  <material name="Red">
    <color rgba="1.0 0.0 0.0 1.0"/>
  </material>
  <material name="Green">
    <color rgba="0.0 1.0 0.0 1.0"/>
  </material>
  <material name="Blue">
    <color rgba="0.0 0.0 0.8 1.0"/>
  </material>
  <material name="LightGrey">
    <color rgba="0.82 0.82 0.82 1.0"/>
  </material>
  <!-- I Module -->
  <!--definition of default_inertial -->
  <!-- T Module -->
  <!--definition of default_inertial -->
  <!-- T Invert Module -->
  <!--definition of default_inertial -->
  <!-- Gripper100 Module -->
  <!--definition of default_inertial -->
  <!-- Gripper100 invert Module -->
  <!--definition of default_inertial -->
  <!-- 100_85_connect_link Module -->
  <!-- t85 Module -->
  <!--definition of macro -->
  <!-- i85  Module -->
  <!--definition of default_inertial -->
  <!-- g85  Module -->
  <!--definition of default_inertial -->
  <!-- Now we can start using the macros included above to define the actual youbot -->
  <!-- The first use of a macro.  This one was defined in base.urdf.xacro above.
       A macro like this will expand to a set of link and joint definitions, and to additional
       Gazebo-related extensions (sensor plugins, etc).  The macro takes an argument, name, 
       that equals "base", and uses it to generate names for its component links and joints 
       (e.g., base_link).  The included origin block is also an argument to the macro.  By convention, 
       the origin block defines where the component is w.r.t its parent (in this case the parent 
       is the world frame). For more, see http://www.ros.org/wiki/xacro -->
  <!-- foot for module arm-->
  <link name="base_link"/>
  <!--  <xacro:G_invert name="G0" parent="base_link">-->
  <!--    <origin xyz="0 0 0.17836" rpy="${-pi*0.5} 0 0" />-->
  <!--  </xacro:G_invert>-->
  <!-- joint between base_link and Lockring_Link -->
  <joint name="I1_joint_0" type="fixed">
    <origin rpy="0 0 0" xyz="0 0 0"/>
    <parent link="base_link"/>
    <child link="I1_Lr_Link_0"/>
  </joint>
  <!--the Lockring_Link in I module-->
  <link name="I1_Lr_Link_0">
    <inertial>
      <origin rpy="0 0 1" xyz="1.7347E-18 4.5022E-17 0.0028047"/>
      <mass value="0.0017728"/>
      <inertia ixx="2.1769E-06" ixy="-6.7209E-37" ixz="8.0356E-39" iyy="2.1769E-06" iyz="-1.0785E-36" izz="4.3442E-06"/>
    </inertial>
    <visual>
      <origin rpy="0 0 0" xyz="0 0 0"/>
      <geometry>
        <mesh filename="package://mr_description/meshes/VI_InLink.STL"/>
      </geometry>
      <material name="White"/>
    </visual>
    <!--    <collision>-->
    <!--      <origin xyz="0 0 0" rpy="0 0 0" />-->
    <!--      <geometry>-->
    <!--        <mesh filename="package://mr_description/meshes/VI_InLink.STL" />-->
    <!--      </geometry>-->
    <!--    </collision>-->
  </link>
  <!-- joint between Lockring_Link and IModule_InLink -->
  <joint name="I1_Lr_Joint_1" type="fixed">
    <origin rpy="0 0 0" xyz="0 0 0"/>
    <parent link="I1_Lr_Link_0"/>
    <child link="I1_InLink_1"/>
    <axis xyz="0 0 0"/>
    <limit effort="0" lower="0" upper="0" velocity="0"/>
  </joint>
  <!--the IModule_InLink in I module-->
  <link name="I1_InLink_1">
    <inertial>
      <origin rpy="0 0 0" xyz="0.0024379 -0.0024994 0.076186"/>
      <mass value="0.58944"/>
      <inertia ixx="0.0012341" ixy="-3.8775E-05" ixz="-3.5596E-05" iyy="0.001235" iyz="3.487E-05" izz="0.00097195"/>
    </inertial>
    <visual>
      <origin rpy="0 0 0" xyz="0 0 0"/>
      <geometry>
        <mesh filename="package://mr_description/meshes/I_InLink.STL"/>
      </geometry>
      <material name="Red"/>
    </visual>
    <collision>
      <!--      <origin   xyz="0 0 0"  rpy="0 0 0" />-->
      <origin rpy="0 0 0" xyz="0 0 0.083"/>
      <geometry>
        <!--        <mesh   filename="package://mr_description/meshes/I_InLink.STL" />-->
        <cylinder length="0.158" radius="0.05"/>
      </geometry>
    </collision>
  </link>
  <!-- joint between IModule_InLink and IModule_OutLink -->
  <joint name="I1_Joint" type="continuous">
    <origin rpy="0 0 0" xyz="0 0 0.12015"/>
    <parent link="I1_InLink_1"/>
    <child link="I1_OutLink_2"/>
    <axis xyz="0 0 1"/>
    <limit effort="75" velocity="1.1"/>
  </joint>
  <!--    test reduction ratio-->
  <transmission name="simple_trans">
    <type>transmission_interface/SimpleTransmission</type>
    <joint name="I1_Joint">
      <hardwareInterface>PositionJointInterface</hardwareInterface>
      <hardwareInterface>VelocityJointInterface</hardwareInterface>
    </joint>
    <actuator name="I1_motor">
      <mechanicalReduction>457</mechanicalReduction>
      <hardwareInterface>PositionJointInterface</hardwareInterface>
      <hardwareInterface>VelocityJointInterface</hardwareInterface>
    </actuator>
  </transmission>
  <!--the IModule_OutLink in I module-->
  <link name="I1_OutLink_2">
    <inertial>
      <origin rpy="0 0 0" xyz="-2.1654E-06 1.6134E-06 0.015967"/>
      <mass value="1.185"/>
      <inertia ixx="0.0008146" ixy="-5.4911E-08" ixz="-2.4725E-08" iyy="0.00081463" iyz="1.7434E-08" izz="0.0013197"/>
    </inertial>
    <visual>
      <origin rpy="0 0 0" xyz="0 0 0"/>
      <geometry>
        <mesh filename="package://mr_description/meshes/I_OutLink.STL"/>
      </geometry>
      <material name="Red"/>
    </visual>
    <!--    <collision>-->
    <!--      <origin  xyz="0 0 0" rpy="0 0 0" />-->
    <!--      <geometry>-->
    <!--        <mesh  filename="package://mr_description/meshes/I_OutLink.STL" />-->
    <!--      </geometry>-->
    <!--    </collision>-->
  </link>
  <!-- joint between IModule_OutLink and Lockring_Link -->
  <joint name="I1_Lr_Joint_3" type="fixed">
    <origin rpy="0 0 0" xyz="0 0 0.0432"/>
    <parent link="I1_OutLink_2"/>
    <child link="I1_Lr_Link_3"/>
    <axis xyz="0 0 0"/>
    <limit effort="0" lower="0" upper="0" velocity="0"/>
  </joint>
  <!--the Lockring_Link in I module-->
  <link name="I1_Lr_Link_3">
    <inertial>
      <origin rpy="0 0 0" xyz="-1.7347E-18 4.5159E-17 -0.00285"/>
      <mass value="0.0017728"/>
      <inertia ixx="2.1769E-06" ixy="-9.5009E-37" ixz="1.6071E-38" iyy="2.1769E-06" iyz="-1.0575E-36" izz="4.3442E-06"/>
    </inertial>
    <visual>
      <origin rpy="0 0 0" xyz="0 0 0"/>
      <geometry>
        <mesh filename="package://mr_description/meshes/VI_OutLink.STL"/>
      </geometry>
      <material name="White"/>
    </visual>
    <!--    <collision>-->
    <!--      <origin  xyz="0 0 0" rpy="0 0 0" />-->
    <!--      <geometry>-->
    <!--        <mesh  filename="package://mr_description/meshes/VI_OutLink.STL" />-->
    <!--      </geometry>-->
    <!--    </collision>-->
  </link>
  <!-- joint between base_link and Lockring_Link -->
  <joint name="T2_joint_0" type="fixed">
    <origin rpy="0 0 0" xyz="0 0 0"/>
    <!--    <origin xyz="0 0 0.005" rpy="0 0 0" />-->
    <parent link="I1_Lr_Link_3"/>
    <child link="T2_Lr_Link_3"/>
  </joint>
  <!--the Lockring_Link in T module-->
  <link name="T2_Lr_Link_3">
    <inertial>
      <origin rpy="0 0 0" xyz="-2.7136E-19 9.8046E-20 -0.0015"/>
      <mass value="8.4823E-05"/>
      <inertia ixx="2.5447E-10" ixy="0" ixz="-1.9769E-26" iyy="2.5447E-10" iyz="9.4423E-27" izz="3.817E-10"/>
    </inertial>
    <visual>
      <origin rpy="0 0 0" xyz="0 0 0"/>
      <geometry>
        <mesh filename="package://mr_description/meshes/VT_OutLink.STL"/>
      </geometry>
      <material name="White"/>
    </visual>
    <!--    <collision>-->
    <!--      <origin  xyz="0 0 0" rpy="0 0 0" />-->
    <!--      <geometry>-->
    <!--        <mesh  filename="package://mr_description/meshes/VT_OutLink.STL" />-->
    <!--      </geometry>-->
    <!--    </collision>   -->
  </link>
  <!-- joint between TModule_OutLink and Lockring_Link -->
  <joint name="T2_Lr_Joint_3" type="fixed">
    <origin rpy="-1.57079632679 3.1416 3.1416" xyz="0 0 0.0884"/>
    <child link="T2_OutLink_2"/>
    <parent link="T2_Lr_Link_3"/>
    <axis xyz="0 0 0"/>
    <limit effort="0" lower="0" upper="0" velocity="0"/>
  </joint>
  <!--the TModule_OutLink in T module-->
  <link name="T2_OutLink_2">
    <inertial>
      <origin rpy="0 0 0" xyz="2.0762E-05 -0.0094284 0.014486"/>
      <mass value="1.4322"/>
      <inertia ixx="0.0018144" ixy="-1.0634E-06" ixz="9.3521E-08" iyy="0.0011673" iyz="8.3209E-05" izz="0.0023046"/>
    </inertial>
    <visual>
      <origin rpy="0 0 0" xyz="0 0 0"/>
      <geometry>
        <mesh filename="package://mr_description/meshes/T_OutLink.STL"/>
      </geometry>
      <material name="Red"/>
    </visual>
    <collision>
      <origin rpy="1.57079632679 0 0" xyz="0 -0.03 0"/>
      <!--      <origin  xyz="0 0 0" rpy="0 0 0" />-->
      <geometry>
        <cylinder length="0.12" radius="0.05"/>
        <!--        <mesh  filename="package://mr_description/meshes/T_OutLink.STL" />-->
      </geometry>
    </collision>
  </link>
  <!-- joint between TModule_InLink and TModule_OutLink -->
  <joint name="T2_Joint" type="revolute">
    <origin rpy="4.7124 -1.2251E-16 3.1416" xyz=" 0 0 0"/>
    <!--    <origin  xyz=" 0 0 -0.1466"  rpy="4.7124 -1.2251E-16 3.1416" />-->
    <child link="T2_InLink_1"/>
    <parent link="T2_OutLink_2"/>
    <axis xyz="0 -1 0"/>
    <limit effort="75" lower="-2.07" upper="2.07" velocity="1.047"/>
  </joint>
  <!--    test reduction ratio-->
  <transmission name="T2_trans">
    <type>transmission_interface/SimpleTransmission</type>
    <joint name="T2_Joint">
      <hardwareInterface>PositionJointInterface</hardwareInterface>
      <hardwareInterface>VelocityJointInterface</hardwareInterface>
      <!--      <hardwareInterface>EffortJointInterface</hardwareInterface>-->
    </joint>
    <actuator name="T2_motor">
      <mechanicalReduction>480</mechanicalReduction>
      <hardwareInterface>PositionJointInterface</hardwareInterface>
      <hardwareInterface>VelocityJointInterface</hardwareInterface>
      <!--      <hardwareInterface>EffortJointInterface</hardwareInterface>-->
    </actuator>
  </transmission>
  <!--the TModule_InLink in T module-->
  <link name="T2_InLink_1">
    <inertial>
      <origin rpy="0 0 0" xyz="4.5327E-06 0.014724 -0.04424"/>
      <!--      <origin xyz="4.5327E-06 0.014724 0.10236-0.1466" rpy="0 0 0" />-->
      <mass value="0.8287"/>
      <inertia ixx="0.0027398" ixy="-8.0424E-07" ixz="-2.3991E-06" iyy="0.0028894" iyz="0.00016467" izz="0.00086451"/>
    </inertial>
    <visual>
      <origin rpy="0 0 0" xyz="0 0 -0.1466"/>
      <geometry>
        <mesh filename="package://mr_description/meshes/T_InLink.STL"/>
      </geometry>
      <material name="Red"/>
    </visual>
    <collision>
      <origin rpy="0 0 0" xyz="0 0 -0.11"/>
      <!--      <origin   xyz="0 0 -0.1466"  rpy="0 0 0" />-->
      <geometry>
        <cylinder length="0.07" radius="0.05"/>
        <!--        <mesh   filename="package://mr_description/meshes/T_InLink.STL" />-->
      </geometry>
    </collision>
  </link>
  <!-- joint between Lockring_Link and TModule_InLink -->
  <joint name="T2_Lr_Joint_1" type="fixed">
    <origin rpy="0 3.1416 0" xyz="0 0 -0.1416"/>
    <child link="T2_Lr_Link_0"/>
    <parent link="T2_InLink_1"/>
    <axis xyz="0 0 0"/>
    <limit effort="0" lower="0" upper="0" velocity="0"/>
  </joint>
  <!--the Lockring_Link in T module-->
  <link name="T2_Lr_Link_0">
    <inertial>
      <origin rpy="0 0 0" xyz="2.9038E-18 -2.1866E-18 0.0015"/>
      <mass value="8.4823E-05"/>
      <inertia ixx="2.5447E-10" ixy="-1.2925E-27" ixz="4.3983E-28" iyy="2.5447E-10" iyz="3.5597E-27" izz="3.817E-10"/>
    </inertial>
    <visual>
      <origin rpy="0 0 0" xyz="0 0 0"/>
      <geometry>
        <mesh filename="package://mr_description/meshes/VT_InLink.STL"/>
      </geometry>
      <material name="White"/>
    </visual>
    <!--    <collision>-->
    <!--      <origin xyz="0 0 0" rpy="0 0 0" />-->
    <!--      <geometry>-->
    <!--        <mesh filename="package://mr_description/meshes/VT_InLink.STL" />-->
    <!--      </geometry>-->
    <!--    </collision>-->
  </link>
  <!-- joint between base_link and Lockring_Link -->
  <joint name="I3_joint_0" type="fixed">
    <origin rpy="0 0 0" xyz="0 0 0.005"/>
    <parent link="T2_Lr_Link_0"/>
    <child link="I3_Lr_Link_0"/>
  </joint>
  <!--the Lockring_Link in I module-->
  <link name="I3_Lr_Link_0">
    <inertial>
      <origin rpy="0 0 1" xyz="1.7347E-18 4.5022E-17 0.0028047"/>
      <mass value="0.0017728"/>
      <inertia ixx="2.1769E-06" ixy="-6.7209E-37" ixz="8.0356E-39" iyy="2.1769E-06" iyz="-1.0785E-36" izz="4.3442E-06"/>
    </inertial>
    <visual>
      <origin rpy="0 0 0" xyz="0 0 0"/>
      <geometry>
        <mesh filename="package://mr_description/meshes/VI_InLink.STL"/>
      </geometry>
      <material name="White"/>
    </visual>
    <!--    <collision>-->
    <!--      <origin xyz="0 0 0" rpy="0 0 0" />-->
    <!--      <geometry>-->
    <!--        <mesh filename="package://mr_description/meshes/VI_InLink.STL" />-->
    <!--      </geometry>-->
    <!--    </collision>-->
  </link>
  <!-- joint between Lockring_Link and IModule_InLink -->
  <joint name="I3_Lr_Joint_1" type="fixed">
    <origin rpy="0 0 0" xyz="0 0 0"/>
    <parent link="I3_Lr_Link_0"/>
    <child link="I3_InLink_1"/>
    <axis xyz="0 0 0"/>
    <limit effort="0" lower="0" upper="0" velocity="0"/>
  </joint>
  <!--the IModule_InLink in I module-->
  <link name="I3_InLink_1">
    <inertial>
      <origin rpy="0 0 0" xyz="0.0024379 -0.0024994 0.076186"/>
      <mass value="0.58944"/>
      <inertia ixx="0.0012341" ixy="-3.8775E-05" ixz="-3.5596E-05" iyy="0.001235" iyz="3.487E-05" izz="0.00097195"/>
    </inertial>
    <visual>
      <origin rpy="0 0 0" xyz="0 0 0"/>
      <geometry>
        <mesh filename="package://mr_description/meshes/I_InLink.STL"/>
      </geometry>
      <material name="Red"/>
    </visual>
    <collision>
      <!--      <origin   xyz="0 0 0"  rpy="0 0 0" />-->
      <origin rpy="0 0 0" xyz="0 0 0.083"/>
      <geometry>
        <!--        <mesh   filename="package://mr_description/meshes/I_InLink.STL" />-->
        <cylinder length="0.158" radius="0.05"/>
      </geometry>
    </collision>
  </link>
  <!-- joint between IModule_InLink and IModule_OutLink -->
  <joint name="I3_Joint" type="continuous">
    <origin rpy="0 0 0" xyz="0 0 0.12015"/>
    <parent link="I3_InLink_1"/>
    <child link="I3_OutLink_2"/>
    <axis xyz="0 0 1"/>
    <limit effort="75" velocity="1.1"/>
  </joint>
  <!--    test reduction ratio-->
  <transmission name="simple_trans">
    <type>transmission_interface/SimpleTransmission</type>
    <joint name="I3_Joint">
      <hardwareInterface>PositionJointInterface</hardwareInterface>
      <hardwareInterface>VelocityJointInterface</hardwareInterface>
    </joint>
    <actuator name="I3_motor">
      <mechanicalReduction>457</mechanicalReduction>
      <hardwareInterface>PositionJointInterface</hardwareInterface>
      <hardwareInterface>VelocityJointInterface</hardwareInterface>
    </actuator>
  </transmission>
  <!--the IModule_OutLink in I module-->
  <link name="I3_OutLink_2">
    <inertial>
      <origin rpy="0 0 0" xyz="-2.1654E-06 1.6134E-06 0.015967"/>
      <mass value="1.185"/>
      <inertia ixx="0.0008146" ixy="-5.4911E-08" ixz="-2.4725E-08" iyy="0.00081463" iyz="1.7434E-08" izz="0.0013197"/>
    </inertial>
    <visual>
      <origin rpy="0 0 0" xyz="0 0 0"/>
      <geometry>
        <mesh filename="package://mr_description/meshes/I_OutLink.STL"/>
      </geometry>
      <material name="Red"/>
    </visual>
    <!--    <collision>-->
    <!--      <origin  xyz="0 0 0" rpy="0 0 0" />-->
    <!--      <geometry>-->
    <!--        <mesh  filename="package://mr_description/meshes/I_OutLink.STL" />-->
    <!--      </geometry>-->
    <!--    </collision>-->
  </link>
  <!-- joint between IModule_OutLink and Lockring_Link -->
  <joint name="I3_Lr_Joint_3" type="fixed">
    <origin rpy="0 0 0" xyz="0 0 0.0432"/>
    <parent link="I3_OutLink_2"/>
    <child link="I3_Lr_Link_3"/>
    <axis xyz="0 0 0"/>
    <limit effort="0" lower="0" upper="0" velocity="0"/>
  </joint>
  <!--the Lockring_Link in I module-->
  <link name="I3_Lr_Link_3">
    <inertial>
      <origin rpy="0 0 0" xyz="-1.7347E-18 4.5159E-17 -0.00285"/>
      <mass value="0.0017728"/>
      <inertia ixx="2.1769E-06" ixy="-9.5009E-37" ixz="1.6071E-38" iyy="2.1769E-06" iyz="-1.0575E-36" izz="4.3442E-06"/>
    </inertial>
    <visual>
      <origin rpy="0 0 0" xyz="0 0 0"/>
      <geometry>
        <mesh filename="package://mr_description/meshes/VI_OutLink.STL"/>
      </geometry>
      <material name="White"/>
    </visual>
    <!--    <collision>-->
    <!--      <origin  xyz="0 0 0" rpy="0 0 0" />-->
    <!--      <geometry>-->
    <!--        <mesh  filename="package://mr_description/meshes/VI_OutLink.STL" />-->
    <!--      </geometry>-->
    <!--    </collision>-->
  </link>
  <!-- joint between base_link and Lockring_Link -->
  <joint name="T4_joint_0" type="fixed">
    <origin rpy="0 0 3.14159265359" xyz="0 0 0"/>
    <parent link="I3_Lr_Link_3"/>
    <child link="T4_Lr_Link_0"/>
  </joint>
  <!--the Lockring_Link in T module-->
  <link name="T4_Lr_Link_0">
    <inertial>
      <origin rpy="0 0 0" xyz="2.9038E-18 -2.1866E-18 0.0015"/>
      <mass value="8.4823E-05"/>
      <inertia ixx="2.5447E-10" ixy="-1.2925E-27" ixz="4.3983E-28" iyy="2.5447E-10" iyz="3.5597E-27" izz="3.817E-10"/>
    </inertial>
    <visual>
      <origin rpy="0 0 0" xyz="0 0 0"/>
      <geometry>
        <mesh filename="package://mr_description/meshes/VT_InLink.STL"/>
      </geometry>
      <material name="White"/>
    </visual>
    <!--    <collision>-->
    <!--      <origin xyz="0 0 0" rpy="0 0 0" />-->
    <!--      <geometry>-->
    <!--        <mesh filename="package://mr_description/meshes/VT_InLink.STL" />-->
    <!--      </geometry>-->
    <!--    </collision>-->
  </link>
  <!-- joint between Lockring_Link and TModule_InLink -->
  <joint name="T4_Lr_Joint_1" type="fixed">
    <origin rpy="0 0 0" xyz="0 0 0"/>
    <parent link="T4_Lr_Link_0"/>
    <child link="T4_InLink_1"/>
    <axis xyz="0 0 0"/>
    <limit effort="0" lower="0" upper="0" velocity="0"/>
  </joint>
  <!--the TModule_InLink in T module-->
  <link name="T4_InLink_1">
    <inertial>
      <origin rpy="0 0 0" xyz="4.5327E-06 0.014724 0.10236"/>
      <mass value="0.8287"/>
      <inertia ixx="0.0027398" ixy="-8.0424E-07" ixz="-2.3991E-06" iyy="0.0028894" iyz="0.00016467" izz="0.00086451"/>
    </inertial>
    <visual>
      <origin rpy="0 0 0" xyz="0 0 0"/>
      <geometry>
        <mesh filename="package://mr_description/meshes/T_InLink.STL"/>
      </geometry>
      <material name="Red"/>
    </visual>
    <collision>
      <origin rpy="0 0 0" xyz="0 0 0.04"/>
      <!--      <origin   xyz="0 0 0"  rpy="0 0 0" />-->
      <geometry>
        <cylinder length="0.07" radius="0.05"/>
        <!--        <mesh   filename="package://mr_description/meshes/T_InLink.STL" />-->
      </geometry>
    </collision>
  </link>
  <!-- joint between TModule_InLink and TModule_OutLink -->
  <joint name="T4_Joint" type="revolute">
    <!--  <joint  name="${name}_Joint"  type="continuous">-->
    <origin rpy="-1.5708 1.2251E-16 -3.1416" xyz="0 0 0.1466"/>
    <parent link="T4_InLink_1"/>
    <child link="T4_OutLink_2"/>
    <axis xyz="0 0 -1"/>
    <limit effort="75" lower="-2.07" upper="2.07" velocity="1.047"/>
  </joint>
  <!--    test reduction ratio-->
  <transmission name="T4_trans">
    <type>transmission_interface/SimpleTransmission</type>
    <joint name="T4_Joint">
      <hardwareInterface>PositionJointInterface</hardwareInterface>
      <hardwareInterface>VelocityJointInterface</hardwareInterface>
      <!--      <hardwareInterface>EffortJointInterface</hardwareInterface>-->
    </joint>
    <actuator name="T4_motor">
      <mechanicalReduction>480</mechanicalReduction>
      <hardwareInterface>PositionJointInterface</hardwareInterface>
      <hardwareInterface>VelocityJointInterface</hardwareInterface>
      <!--      <hardwareInterface>EffortJointInterface</hardwareInterface>-->
    </actuator>
  </transmission>
  <!--the TModule_OutLink in T module-->
  <link name="T4_OutLink_2">
    <inertial>
      <origin rpy="0 0 0" xyz="2.0762E-05 -0.0094284 0.014486"/>
      <mass value="1.4322"/>
      <inertia ixx="0.0018144" ixy="-1.0634E-06" ixz="9.3521E-08" iyy="0.0011673" iyz="8.3209E-05" izz="0.0023046"/>
    </inertial>
    <visual>
      <origin rpy="0 0 0" xyz="0 0 0"/>
      <geometry>
        <mesh filename="package://mr_description/meshes/T_OutLink.STL"/>
      </geometry>
      <material name="Red"/>
    </visual>
    <collision>
      <origin rpy="1.57079632679 0 0" xyz="0 -0.025 0"/>
      <!--      <origin  xyz="0 0 0" rpy="0 0 0" />-->
      <geometry>
        <cylinder length="0.12" radius="0.05"/>
        <!--        <mesh  filename="package://mr_description/meshes/T_OutLink.STL" />-->
      </geometry>
    </collision>
  </link>
  <!-- joint between TModule_OutLink and Lockring_Link -->
  <joint name="T4_Lr_Joint_3" type="fixed">
    <origin rpy="-1.5708 0 3.1416" xyz="0 -0.0934 0"/>
    <parent link="T4_OutLink_2"/>
    <child link="T4_Lr_Link_3"/>
    <axis xyz="0 0 0"/>
    <limit effort="0" lower="0" upper="0" velocity="0"/>
  </joint>
  <!--the Lockring_Link in T module-->
  <link name="T4_Lr_Link_3">
    <inertial>
      <origin rpy="0 0 0" xyz="-2.7136E-19 9.8046E-20 -0.0015"/>
      <mass value="8.4823E-05"/>
      <inertia ixx="2.5447E-10" ixy="0" ixz="-1.9769E-26" iyy="2.5447E-10" iyz="9.4423E-27" izz="3.817E-10"/>
    </inertial>
    <visual>
      <origin rpy="0 0 0" xyz="0 0 0"/>
      <geometry>
        <mesh filename="package://mr_description/meshes/VT_OutLink.STL"/>
      </geometry>
      <material name="White"/>
    </visual>
    <!--    <collision>-->
    <!--      <origin  xyz="0 0 0" rpy="0 0 0" />-->
    <!--      <geometry>-->
    <!--        <mesh  filename="package://mr_description/meshes/VT_OutLink.STL" />-->
    <!--      </geometry>-->
    <!--    </collision>   -->
  </link>
  <!-- joint between parent_link and connect_link -->
  <joint name="cl_joint_0" type="fixed">
    <origin rpy="0 0 0" xyz="0 0 0"/>
    <parent link="T4_Lr_Link_3"/>
    <child link="cl_100_85_connect_link"/>
  </joint>
  <link name="cl_100_85_connect_link">
    <inertial>
      <origin rpy="0 0 0" xyz="-1.27516786158077E-08 2.74027707044729E-07 0.0111947608030705"/>
      <mass value="0.0438125444482135"/>
      <inertia ixx="4.51431123366934E-05" ixy="6.46792512162578E-11" ixz="2.3639761869618E-11" iyy="4.51508010910367E-05" iyz="8.30065030221648E-12" izz="8.49096146689648E-05"/>
    </inertial>
    <visual>
      <origin rpy="0 0 0" xyz="0 0 0"/>
      <geometry>
        <mesh filename="package://mr_description/meshes/100-85_connect_link.STL"/>
      </geometry>
      <material name="">
        <color rgba="1 0 0 1"/>
      </material>
    </visual>
    <collision>
      <origin rpy="0 0 0" xyz="0 0 0.011"/>
      <geometry>
        <!--        <mesh  filename="package://mr_description/meshes/100-85_connect_link.STL" />-->
        <cylinder length="0.022" radius="0.0425"/>
      </geometry>
    </collision>
  </link>
  <link name="cl_100_85_connect_link2"/>
  <joint name="cl_fixed" type="fixed">
    <origin rpy="0 0 0" xyz="0 0 0.0236"/>
    <parent link="cl_100_85_connect_link"/>
    <child link="cl_100_85_connect_link2"/>
    <axis xyz="0 0 0"/>
  </joint>
  <!-- joint between base_link and Lockring_Link -->
  <joint name="i5_joint_0" type="fixed">
    <origin rpy="0 0 0" xyz="0 0 0"/>
    <parent link="cl_100_85_connect_link2"/>
    <child link="i5_link"/>
  </joint>
  <link name="i5_link">
    <inertial>
      <origin rpy="0 0 0" xyz="-0.00109121633873397 -0.000198050872652557 0.0542417178246159"/>
      <mass value="0.389080654611604"/>
      <inertia ixx="0.000528345508911097" ixy="1.18007724874168E-06" ixz="3.55201744524765E-06" iyy="0.000587990280546246" iyz="1.46979659751903E-06" izz="0.000472243050258981"/>
    </inertial>
    <visual>
      <origin rpy="0 0 0" xyz="0 0 0"/>
      <geometry>
        <mesh filename="package://mr_description/meshes/i_link.STL"/>
      </geometry>
      <material name="">
        <color rgba="0.866666666666667 0 0 1"/>
      </material>
    </visual>
    <collision>
      <origin rpy="0 0 0" xyz="0 0 0.072"/>
      <geometry>
        <!--        <mesh  filename="package://mr_description/meshes/i_link.STL" />-->
        <cylinder length="0.144" radius="0.0425"/>
      </geometry>
    </collision>
  </link>
  <link name="i5_link2">
    <inertial>
      <origin rpy="0 0 0" xyz="-2.4633E-14 3.7186E-08 -0.022781"/>
      <mass value="0.80864"/>
      <inertia ixx="0.00042548" ixy="8.2396E-17" ixz="-4.0773E-17" iyy="0.00042548" iyz="-6.6735E-11" izz="0.00069524"/>
    </inertial>
    <visual>
      <origin rpy="0 0 0" xyz="0 0 0"/>
      <geometry>
        <mesh filename="package://mr_description/meshes/i_link2.STL"/>
      </geometry>
      <material name="">
        <color rgba="0.86667 0 0 1"/>
      </material>
    </visual>
    <!--    <collision>-->
    <!--      <origin  xyz="0 0 0" rpy="0 0 0" />-->
    <!--      <geometry>-->
    <!--        <mesh  filename="package://mr_description/meshes/i_link2.STL" />-->
    <!--      </geometry>-->
    <!--    </collision>-->
  </link>
  <joint name="i5_Joint" type="continuous">
    <origin rpy="-8.5591E-29 0 0" xyz="0 0 0.137"/>
    <parent link="i5_link"/>
    <child link="i5_link2"/>
    <axis xyz="0 0 1"/>
    <limit effort="30" lower="-3.1416" upper="3.1416" velocity="1.29"/>
    <calibration falling="1" rising="1"/>
    <dynamics damping="1" friction="1"/>
    <safety_controller k_position="1" k_velocity="1" soft_lower="-3.1416" soft_upper="3.1416"/>
  </joint>
  <!--    test reduction ratio-->
  <transmission name="simple_trans">
    <type>transmission_interface/SimpleTransmission</type>
    <joint name="i5_Joint">
      <hardwareInterface>PositionJointInterface</hardwareInterface>
      <hardwareInterface>VelocityJointInterface</hardwareInterface>
    </joint>
    <actuator name="i5_motor">
      <mechanicalReduction>226</mechanicalReduction>
      <hardwareInterface>PositionJointInterface</hardwareInterface>
      <hardwareInterface>VelocityJointInterface</hardwareInterface>
    </actuator>
  </transmission>
  <!-- joint between parent-link and module_Link -->
  <joint name="t6_joint_0" type="fixed">
    <origin rpy="0 0 -1.57079632679" xyz="0 0 0"/>
    <parent link="i5_link2"/>
    <child link="t6_link"/>
  </joint>
  <link name="t6_link">
    <inertial>
      <origin rpy="0 0 0" xyz="-0.0180255383176995 2.00182271818558E-05 0.063920300127545"/>
      <mass value="0.832217409872162"/>
      <inertia ixx="0.00162292630009161" ixy="5.16386324388829E-07" ixz="-5.38220794323839E-05" iyy="0.00161884419291852" iyz="-1.03737233460529E-06" izz="0.000486359497324985"/>
    </inertial>
    <visual>
      <origin rpy="0 0 0" xyz="0 0 0"/>
      <geometry>
        <mesh filename="package://mr_description/meshes/t_link.STL"/>
      </geometry>
      <material name="">
        <color rgba="0.8 0 0 1"/>
      </material>
    </visual>
    <collision>
      <origin rpy="0 0 0" xyz="0 0 0.034"/>
      <geometry>
        <!--        <mesh filename="package://mr_description/meshes/t_link.STL" />-->
        <cylinder length="0.052" radius="0.0425"/>
      </geometry>
    </collision>
  </link>
  <link name="t6_link2">
    <visual>
      <origin rpy="0 0 0" xyz="0 0 0.0825"/>
      <geometry>
        <mesh filename="package://mr_description/meshes/t_link2.STL"/>
      </geometry>
      <material name="">
        <color rgba="0.86667 0 0 1"/>
      </material>
    </visual>
    <collision>
      <origin rpy="0 0 0" xyz="0 0 0.0175"/>
      <geometry>
        <!--        <mesh filename="package://mr_description/meshes/t_link2.STL" />-->
        <cylinder length="0.125" radius="0.0425"/>
      </geometry>
    </collision>
    <inertial>
      <origin rpy="0 0 0" xyz="-0.01642 2.1934E-05 -0.007293"/>
      <mass value="0.98367"/>
      <inertia ixx="0.0012164" ixy="8.6247E-07" ixz="7.8271E-05" iyy="0.00097611" iyz="-1.2736E-07" izz="0.00062614"/>
    </inertial>
  </link>
  <joint name="t6_Joint" type="revolute">
    <origin rpy="0 0 3.1416" xyz="0 0 0.131"/>
    <parent link="t6_link"/>
    <child link="t6_link2"/>
    <axis xyz="1 0 0"/>
    <limit effort="28" lower="-2.09" upper="2.09" velocity="2.09"/>
    <calibration falling="0" rising="0"/>
    <dynamics damping="0" friction="0"/>
    <!--    <safety_controller soft_upper="-2.07" soft_lower="2.07"  k_position="0" k_velocity="0" />-->
  </joint>
  <!--  reduction ratio-->
  <transmission name="simple_trans">
    <type>transmission_interface/SimpleTransmission</type>
    <joint name="t6_Joint">
      <hardwareInterface>PositionJointInterface</hardwareInterface>
      <hardwareInterface>VelocityJointInterface</hardwareInterface>
    </joint>
    <actuator name="t6_motor">
      <mechanicalReduction>200</mechanicalReduction>
      <hardwareInterface>PositionJointInterface</hardwareInterface>
      <hardwareInterface>VelocityJointInterface</hardwareInterface>
    </actuator>
  </transmission>
  <!-- joint between base_link and Lockring_Link -->
  <joint name="g7_joint_0" type="fixed">
    <origin rpy="0 0 0" xyz="0 0 0.0825"/>
    <parent link="t6_link2"/>
    <child link="g7_palm_link"/>
  </joint>
  <link name="g7_palm_link">
    <visual>
      <origin rpy="0 0 0" xyz="0 0 0"/>
      <geometry>
        <mesh filename="package://mr_description/meshes/g_palm_link.STL"/>
      </geometry>
      <material name="">
        <color rgba="0.1 0.1 0.1 1"/>
      </material>
    </visual>
    <collision>
      <origin rpy="0 0 0" xyz="0 0 0.028"/>
      <geometry>
        <!--        <mesh  filename="package://mr_description/meshes/g_palm_link.STL" />-->
        <cylinder length="0.056" radius="0.0425"/>
      </geometry>
    </collision>
    <inertial>
      <origin rpy="0 0 0" xyz="0.00425087794620391 -0.000341076549934847 0.0434713557042779"/>
      <mass value="0.566653469628951"/>
      <inertia ixx="0.000498497223548746" ixy="5.36329649188159E-07" ixz="-4.07818737202901E-05" iyy="0.000730511793998383" iyz="-6.03266058697901E-06" izz="0.000502182372067087"/>
    </inertial>
  </link>
  <link name="g7_finger_link">
    <visual>
      <origin rpy="0 0 0" xyz="0 0 0"/>
      <geometry>
        <mesh filename="package://mr_description/meshes/g_finger_link.STL"/>
      </geometry>
      <material name="">
        <color rgba="0.1 0.1 0.1 1"/>
      </material>
    </visual>
    <collision>
      <origin rpy="0 0 0" xyz="0 0 0"/>
      <geometry>
        <mesh filename="package://mr_description/meshes/g_finger_link.STL"/>
      </geometry>
    </collision>
    <inertial>
      <origin rpy="0 0 0" xyz="-0.0142537929479308 0.000230061402547915 0.123240994639791"/>
      <mass value="0.0587979869361216"/>
      <inertia ixx="4.06347072846223E-05" ixy="2.52194515964668E-08" ixz="9.16297919180235E-06" iyy="4.29642140065611E-05" iyz="3.2622913893542E-08" izz="9.72727638920999E-06"/>
    </inertial>
  </link>
  <joint name="g7_Joint" type="prismatic">
    <origin rpy="0 0 0" xyz="0 0 0"/>
    <parent link="g7_palm_link"/>
    <child link="g7_finger_link"/>
    <axis xyz="-1 0 0"/>
    <limit effort="1" lower="0" upper="0.06" velocity="0.06"/>
    <!--    <calibration   rising="1"   falling="1" />-->
    <!--    <dynamics    damping="1"    friction="1" />-->
    <!--    <safety_controller soft_upper="0.06" soft_lower="0" k_position="1" k_velocity="1" />-->
  </joint>
  <link name="g7_finger_link1">
    <inertial>
      <origin rpy="0 0 0" xyz="0.0142537929479934 3.43816122645394E-05 0.123240994639808"/>
      <mass value="0.0587979869361215"/>
      <inertia ixx="4.06348713317454E-05" ixy="4.84294028883443E-09" ixz="-9.16297919179846E-06" iyy="4.29642140065595E-05" iyz="-7.56625401696782E-08" izz="9.72744043633773E-06"/>
    </inertial>
    <visual>
      <origin rpy="0 0 0" xyz="0 0 0"/>
      <geometry>
        <mesh filename="package://mr_description/meshes/g_finger_link1.STL"/>
      </geometry>
      <material name="">
        <color rgba="0.1 0.1 0.1 1"/>
      </material>
    </visual>
    <collision>
      <origin rpy="0 0 0" xyz="0 0 0"/>
      <geometry>
        <mesh filename="package://mr_description/meshes/g_finger_link1.STL"/>
      </geometry>
    </collision>
  </link>
  <joint name="g7_Joint1" type="prismatic">
    <origin rpy="0 0 0" xyz="0 0 0"/>
    <parent link="g7_palm_link"/>
    <child link="g7_finger_link1"/>
    <axis xyz="1 0 0"/>
    <limit effort="1" lower="0" upper="0.06" velocity="0.06"/>
    <!--    <calibration  rising="1" />-->
    <!--    <dynamics  damping="1"  friction="1" />-->
    <!--    <safety_controller soft_upper="0.06" soft_lower="0" k_position="1" k_velocity="1" />-->
  </joint>
  <joint name="tcp_fixed_joint" type="fixed">
    <origin rpy="0 0 0" xyz="0 0 0.16"/>
    <parent link="g7_palm_link"/>
    <child link="tcp"/>
  </joint>
  <link name="tcp"/>
  <!--  <xacro:G_module name="G6" parent="T5_Lr_Link_3">-->
  <!--    <origin xyz="0 0 0" rpy="${pi*0.5} 0 ${pi*0.5}" />-->
  <!--  </xacro:G_module>-->
  <!--  <xacro:I_module name="_I5" parent="base_link">-->
  <!--    <origin xyz="0.2 0 0" rpy="0 0 0" />-->
  <!--  </xacro:I_module>-->
  <!--  <xacro:T_module name="_T4" parent="_I5_Lr_Link_3">-->
  <!--    <origin xyz="0 0 0" rpy="0 0 0" />-->
  <!--  </xacro:T_module>-->
  <!--  -->
  <!--  <xacro:T_invert name="_T3" parent="_T4_Lr_Link_3">-->
  <!--  </xacro:T_invert>-->
  <!--  <xacro:T_module name="_T2" parent="_T3_Lr_Link_0">-->
  <!--    <origin xyz="0 0 0" rpy="0 0 0" />-->
  <!--  </xacro:T_module>-->
  <!--  <xacro:I_module name="_I1" parent="_T2_Lr_Link_3">-->
  <!--    <origin xyz="0 0 0" rpy="0 0 0" />-->
  <!--  </xacro:I_module>-->
  <!--  -->
  <!--  <xacro:G_module name="_G0" parent="_I1_Lr_Link_3">-->
  <!--    <origin xyz="0 0 0" rpy="${pi*0.5} 0 0" />-->
  <!--  </xacro:G_module>-->
</robot>

