<?xml version="1.0"?>
<robot xmlns:xacro="http://www.ros.org/wiki/xacro">


<!--definition of default_inertial -->
<xacro:macro name="I_invert" params="parent name *origin rotate_direction_pos:=1">

<!-- joint between base_link and Lockring_Link -->
	<joint name="${name}_joint_0" type="fixed" >
		<insert_block name="origin" />
		<parent link="${parent}" />
		<child link="${name}_Lr_Link_0" />
	</joint>

<!--the Lockring_Link in I module-->
  <link name="${name}_Lr_Link_0">
    <inertial>
      <origin xyz="1.7347E-18 4.5022E-17 0.0028047" rpy="0 0 1" />
      <mass value="0.0017728" />
      <inertia ixx="2.1769E-06" ixy="-6.7209E-37" ixz="8.0356E-39" 
               iyy="2.1769E-06" iyz="-1.0785E-36" izz="4.3442E-06"/>
    </inertial>
    <visual>
      <origin xyz="0 0 0" rpy="0 0 0" />
      <geometry>
        <mesh filename="package://mr_description/meshes/VI_InLink.STL" />
      </geometry>
      <material name="White"/>
    </visual>
<!--    <collision>-->
<!--      <origin xyz="0 0 0" rpy="0 0 0" />-->
<!--      <geometry>-->
<!--        <mesh filename="package://mr_description/meshes/VI_InLink.STL" />-->
<!--      </geometry>-->
<!--    </collision>-->
  </link>

<!-- joint between Lockring_Link and IModule_InLink -->
    <joint name="${name}_Lr_Joint_1" type="fixed">
      <origin xyz="0 0 0" rpy="0 0 0" />
      <parent link="${name}_Lr_Link_0" />
      <child  link="${name}_InLink_1" />
      <axis   xyz="0 0 0" />
      <limit  lower="0" upper="0"  effort="0"   velocity="0" />
    </joint>

<!--the IModule_InLink in I module-->
  <link name="${name}_InLink_1">
    <inertial>
      <origin xyz="0.0024379 -0.0024994 0.076186" rpy="0 0 0" />
      <mass   value="0.58944" />
      <inertia  ixx="0.0012341"  ixy="-3.8775E-05"  ixz="-3.5596E-05"
      				  iyy="0.001235"   iyz="3.487E-05"    izz="0.00097195" />
    </inertial>
    <visual>
      <origin   xyz="0 0 0"  rpy="0 0 0" />
      <geometry>
        <mesh   filename="package://mr_description/meshes/I_InLink.STL" />
      </geometry>
      <material name="Red"/>
    </visual>
    <collision>
<!--      <origin   xyz="0 0 0"  rpy="0 0 0" />-->
	    <origin   xyz="0 0 0.083"  rpy="0 0 0" />
      <geometry>
<!--        <mesh   filename="package://mr_description/meshes/I_InLink.STL" />-->
	      <cylinder radius="0.05" length="0.158"  />
      </geometry>
    </collision>
  </link>
  <!--the IModule_InLink Gazebo tag-->
  <gazebo reference="${name}_InLink_1">
    <material>Gazebo/Red</material>
  </gazebo>

<!-- joint between IModule_InLink and IModule_OutLink -->
  <joint  name="${name}_Joint"  type="continuous">
    <origin  xyz="0 0 0.12015" rpy="0 0 0" />
    <parent  link="${name}_InLink_1" />
    <child   link="${name}_OutLink_2" />

<!--    <xacro:if value="${rotate_direction_pos}">-->
<!--       <axis   xyz="0 0 1" />-->
<!--    </xacro:if>-->
<!--    <xacro:unless value="${rotate_direction_pos}">-->
<!--       <axis   xyz="0 0 -1" />-->
<!--    </xacro:unless>-->
    <axis   xyz="0 0 ${rotate_direction_pos}" />
    <dynamics damping="0.7"/> 
    <limit   effort="75"  velocity="1.1" />
  </joint>
  
  
  <!--    test reduction ratio-->
  <transmission name="${name}_trans">
    <type>transmission_interface/SimpleTransmission</type>
    <joint name="${name}_Joint">
      <hardwareInterface>PositionJointInterface</hardwareInterface>
      <hardwareInterface>VelocityJointInterface</hardwareInterface>
      <hardwareInterface>EffortJointInterface</hardwareInterface>
    </joint>
    <actuator name="${name}_motor">
      <mechanicalReduction>457</mechanicalReduction> 
      <hardwareInterface>PositionJointInterface</hardwareInterface>
      <hardwareInterface>VelocityJointInterface</hardwareInterface>
      <hardwareInterface>EffortJointInterface</hardwareInterface>
    </actuator>
  </transmission>

<!--the IModule_OutLink in I module-->
  <link  name="${name}_OutLink_2">
    <inertial>  
			<origin  xyz="-2.1654E-06 1.6134E-06 0.015967" rpy="0 0 0" />
      <mass    value="1.185" />
      <inertia  ixx="0.0008146"  ixy="-5.4911E-08"  ixz="-2.4725E-08"
       				  iyy="0.00081463" iyz="1.7434E-08"   izz="0.0013197" />
    </inertial>
    <visual>
      <origin  xyz="0 0 0"  rpy="0 0 0" />
      <geometry>
        <mesh  filename="package://mr_description/meshes/I_OutLink.STL" />
      </geometry>
      <material  name="Red"/>
    </visual>
<!--    <collision>-->
<!--      <origin  xyz="0 0 0" rpy="0 0 0" />-->
<!--      <geometry>-->
<!--        <mesh  filename="package://mr_description/meshes/I_OutLink.STL" />-->
<!--      </geometry>-->
<!--    </collision>-->
  </link>
 <!--the IModule_InLink Gazebo tag-->
  <gazebo reference="${name}_OutLink_2">
    <material>Gazebo/Red</material>
  </gazebo>

<!-- joint between IModule_OutLink and Lockring_Link -->
    <joint name="${name}_Lr_Joint_3" type="fixed">
      <origin xyz="0 0 0.0432" rpy="0 0 0" />
      <parent link="${name}_OutLink_2" />
      <child  link="${name}_Link" />
      <axis   xyz="0 0 0" />
      <limit  lower="0" upper="0"  effort="0"   velocity="0" />
    </joint>

<!--the Lockring_Link in I module-->
  <link name="${name}_Link">
    <inertial>
      <origin  xyz="-1.7347E-18 4.5159E-17 -0.00285"  rpy="0 0 0" />
      <mass    value="0.0017728" />
      <inertia   ixx="2.1769E-06"  ixy="-9.5009E-37"  ixz="1.6071E-38"
                 iyy="2.1769E-06"  iyz="-1.0575E-36"  izz="4.3442E-06" />
    </inertial>
    <visual>
      <origin  xyz="0 0 0"  rpy="0 0 0" />
      <geometry>
        <mesh  filename="package://mr_description/meshes/VI_OutLink.STL" />
      </geometry>
      <material name="White"/>
    </visual>
<!--    <collision>-->
<!--      <origin  xyz="0 0 0" rpy="0 0 0" />-->
<!--      <geometry>-->
<!--        <mesh  filename="package://mr_description/meshes/VI_OutLink.STL" />-->
<!--      </geometry>-->
<!--    </collision>-->
  </link>




</xacro:macro>
</robot>
