<robot  name="I_module">

<!--the front visual link in I module-->
  <link name="VI_InLink">
    <inertial>
      <origin xyz="1.7347E-18 4.5022E-17 0.0028047" rpy="0 0 0" />
      <mass value="0.0017728" />
      <inertia ixx="2.1769E-06" ixy="-6.7209E-37" ixz="8.0356E-39" 
               iyy="2.1769E-06" iyz="-1.0785E-36" izz="4.3442E-06"/>
    </inertial>
    <visual>
      <origin xyz="0 0 0" rpy="0 0 0" />
      <geometry>
        <mesh filename="package://mr_description/meshes/VI_InLink.STL" />
      </geometry>
      <material name="">
        <color  rgba="1 1 1 1" />
      </material>
    </visual>
    <collision>
      <origin xyz="0 0 0" rpy="0 0 0" />
      <geometry>
        <mesh filename="package://mr_description/meshes/VI_InLink.STL" />
      </geometry>
    </collision>
  </link>

<!--the front link in I module and the joint fixed with the front visual link-->
  <link name="I_InLink">
    <inertial>
      <origin xyz="0.0024379 -0.0024994 0.076186" rpy="0 0 0" />
      <mass   value="0.58944" />
      <inertia  ixx="0.0012341"  ixy="-3.8775E-05"  ixz="-3.5596E-05"
      				  iyy="0.001235"   iyz="3.487E-05"    izz="0.00097195" />
    </inertial>
    <visual>
      <origin   xyz="0 0 0"  rpy="0 0 0" />
      <geometry>
        <mesh   filename="package://mr_description/meshes/I_InLink.STL" />
      </geometry>
      <material name="">
        <color  rgba="1 0 0 1" />
      </material>
    </visual>
    <collision>
      <origin   xyz="0 0 0"  rpy="0 0 0" />
      <geometry>
        <mesh   filename="package://mr_description/meshes/I_InLink.STL" />
      </geometry>
    </collision>
  </link>
  
  
  <joint name="VI_InJoint" type="fixed">
    <origin xyz="0 0 0" rpy="0 0 0" />
    <parent link="VI_InLink" />
    <child  link="I_InLink" />
    <axis   xyz="0 0 0" />
    <limit  lower="-3.14" upper="3.14"  effort="0"   velocity="0" />
  </joint>

<!--the backend link in I module the joint in I module-->
  <link  name="I_OutLink">
    <inertial>  
			<origin  xyz="-2.1654E-06 1.6134E-06 0.015967" rpy="0 0 0" />
      <mass    value="1.185" />
      <inertia  ixx="0.0008146"  ixy="-5.4911E-08"  ixz="-2.4725E-08"
       				  iyy="0.00081463" iyz="1.7434E-08"   izz="0.0013197" />
    </inertial>
    <visual>
      <origin  xyz="0 0 0"  rpy="0 0 0" />
      <geometry>
        <mesh  filename="package://mr_description/meshes/I_OutLink.STL" />
      </geometry>
      <material  name="">
        <color   rgba="1 0 0 1" />
      </material>
    </visual>
    <collision>
      <origin  xyz="0 0 0" rpy="0 0 0" />
      <geometry>
        <mesh  filename="package://mr_description/meshes/I_OutLink.STL" />
      </geometry>
    </collision>
  </link>
  
  
  <joint  name="I_Joint"  type="revolute">
    <origin  xyz="0 0 0.12015" rpy="0 0 0" />
    <parent  link="I_InLink" />
    <child   link="I_OutLink" />
    <axis   xyz="0 0 1" />
    <limit  lower="-3.14"  upper="3.14"  effort="0"  velocity="0" />
  </joint>

<!--the back visual link in I module and the joint fixed with the front visual link-->
  <link name="VI_OutLink">
    <inertial>
      <origin  xyz="-1.7347E-18 4.5159E-17 -0.00285"  rpy="0 0 0" />
      <mass    value="0.0017728" />
      <inertia   ixx="2.1769E-06"  ixy="-9.5009E-37"  ixz="1.6071E-38"
                 iyy="2.1769E-06"  iyz="-1.0575E-36"  izz="4.3442E-06" />
    </inertial>
    <visual>
      <origin  xyz="0 0 0"  rpy="0 0 0" />
      <geometry>
        <mesh  filename="package://mr_description/meshes/VI_OutLink.STL" />
      </geometry>
      <material name="">
        <color  rgba="1 1 1 1" />
      </material>
    </visual>
    <collision>
      <origin  xyz="0 0 0" rpy="0 0 0" />
      <geometry>
        <mesh  filename="package://mr_description/meshes/VI_OutLink.STL" />
      </geometry>
    </collision>
  </link>
  
  
  <joint name="VI_OutJoint" type="fixed">
    <origin  xyz="0 0 0.0432" rpy="0 0 0" />
    <parent  link="I_OutLink" />
    <child   link="VI_OutLink" />
    <axis    xyz="0 0 0" />
    <limit   lower="-3.14"  upper="3.14"   effort="0"  velocity="0" />
  </joint>


</robot>
